Workbook

Sheet Dashboard
A1: DASHBOARD MONITORING PIUTANG
A2: ="Posisi per "&TEXT(Catatan!B3,"dd mmm yyyy")&" | Data sintetis (fiktif) Jan-Des 2025" -> Posisi per 31 Dec 2025 | Data sintetis (fiktif) Jan-Des 2025
A3: Indikator | B3: Nilai | D3: Kategori Aging | E3: Sisa Piutang (Rp) | F3: % dari Total | G3: Jumlah Faktur
A4: Total Penjualan (Rp) | B4: =SUM(Piutang!F2:F1751) -> 18552147600 | D4: Belum Jatuh Tempo | E4: =SUMIFS(Piutang!$M$2:$M$1751,Piutang!$P$2:$P$1751,D4) -> 738129100 | F4: =IF($E$9=0,0,E4/$E$9) -> 0.61075625 | G4: =COUNTIFS(Piutang!$P$2:$P$1751,D4,Piutang!$M$2:$M$1751,">0") -> 82
A5: Total Piutang Outstanding (Rp) | B5: =SUM(Piutang!M2:M1751) -> 1208549400 | D5: 1-30 hari | E5: =SUMIFS(Piutang!$M$2:$M$1751,Piutang!$P$2:$P$1751,D5) -> 204807200 | F5: =IF($E$9=0,0,E5/$E$9) -> 0.16946531 | G5: =COUNTIFS(Piutang!$P$2:$P$1751,D5,Piutang!$M$2:$M$1751,">0") -> 26
A6: Piutang Overdue (Rp) | B6: =Aging_Customer!J127 -> 470420300 | D6: 31-60 hari | E6: =SUMIFS(Piutang!$M$2:$M$1751,Piutang!$P$2:$P$1751,D6) -> 91756900 | F6: =IF($E$9=0,0,E6/$E$9) -> 0.075923169 | G6: =COUNTIFS(Piutang!$P$2:$P$1751,D6,Piutang!$M$2:$M$1751,">0") -> 10
A7: % Overdue terhadap Piutang | B7: =IF(B5=0,0,B6/B5) -> 0.38924375 | D7: 61-90 hari | E7: =SUMIFS(Piutang!$M$2:$M$1751,Piutang!$P$2:$P$1751,D7) -> 28989900 | F7: =IF($E$9=0,0,E7/$E$9) -> 0.023987352 | G7: =COUNTIFS(Piutang!$P$2:$P$1751,D7,Piutang!$M$2:$M$1751,">0") -> 5
A8: Piutang 90+ hari (Rp) | B8: =SUMIFS(Piutang!M2:M1751,Piutang!P2:P1751,"90+ hari") -> 144866300 | D8: 90+ hari | E8: =SUMIFS(Piutang!$M$2:$M$1751,Piutang!$P$2:$P$1751,D8) -> 144866300 | F8: =IF($E$9=0,0,E8/$E$9) -> 0.11986792 | G8: =COUNTIFS(Piutang!$P$2:$P$1751,D8,Piutang!$M$2:$M$1751,">0") -> 26
A9: Jumlah Faktur Belum Lunas | B9: =COUNTIF(Piutang!M2:M1751,">0") -> 149 | D9: TOTAL | E9: =SUM(E4:E8) -> 1208549400 | F9: =SUM(F4:F8) -> 1 | G9: =SUM(G4:G8) -> 149
A10: Perkiraan DSO (hari) | B10: =IF(B4=0,0,B5/B4*365) -> 23.77733
A11: Faktur Belum Ditukar | B11: =COUNTIF(Piutang!J2:J1751,"Belum ditukar") -> 9
A14: PIUTANG PER SALESMAN | G14: PENJUALAN VS SISA PIUTANG PER BULAN FAKTUR
A15: Salesman | B15: Total Penjualan (Rp) | C15: Sisa Piutang (Rp) | D15: Overdue (Rp) | E15: % Overdue | G15: Bulan | H15: Penjualan (Rp) | I15: Sisa Piutang (Rp)
A16: SALES A | B16: =SUMIFS(Piutang!$F$2:$F$1751,Piutang!$E$2:$E$1751,A16) -> 3094375500 | C16: =SUMIFS(Piutang!$M$2:$M$1751,Piutang!$E$2:$E$1751,A16) -> 165156700 | D16: =C16-SUMIFS(Piutang!$M$2:$M$1751,Piutang!$E$2:$E$1751,A16,Piutang!$P$2:$P$1751,"Belum Jatuh Tempo") -> 54551000 | E16: =IF(C16=0,0,D16/C16) -> 0.33029844 | G16: 45658 | H16: =SUMIFS(Piutang!$F$2:$F$1751,Piutang!$B$2:$B$1751,">="&G16,Piutang!$B$2:$B$1751,"<"&EDATE(G16,1)) -> 1576054400 | I16: =SUMIFS(Piutang!$M$2:$M$1751,Piutang!$B$2:$B$1751,">="&G16,Piutang!$B$2:$B$1751,"<"&EDATE(G16,1)) -> 9360800
A17: SALES B | B17: =SUMIFS(Piutang!$F$2:$F$1751,Piutang!$E$2:$E$1751,A17) -> 3181979800 | C17: =SUMIFS(Piutang!$M$2:$M$1751,Piutang!$E$2:$E$1751,A17) -> 275669700 | D17: =C17-SUMIFS(Piutang!$M$2:$M$1751,Piutang!$E$2:$E$1751,A17,Piutang!$P$2:$P$1751,"Belum Jatuh Tempo") -> 95769400 | E17: =IF(C17=0,0,D17/C17) -> 0.34740633 | G17: 45689 | H17: =SUMIFS(Piutang!$F$2:$F$1751,Piutang!$B$2:$B$1751,">="&G17,Piutang!$B$2:$B$1751,"<"&EDATE(G17,1)) -> 1525951100 | I17: =SUMIFS(Piutang!$M$2:$M$1751,Piutang!$B$2:$B$1751,">="&G17,Piutang!$B$2:$B$1751,"<"&EDATE(G17,1)) -> 39694000
A18: SALES C | B18: =SUMIFS(Piutang!$F$2:$F$1751,Piutang!$E$2:$E$1751,A18) -> 3637198600 | C18: =SUMIFS(Piutang!$M$2:$M$1751,Piutang!$E$2:$E$1751,A18) -> 259719600 | D18: =C18-SUMIFS(Piutang!$M$2:$M$1751,Piutang!$E$2:$E$1751,A18,Piutang!$P$2:$P$1751,"Belum Jatuh Tempo") -> 111393500 | E18: =IF(C18=0,0,D18/C18) -> 0.42889909 | G18: 45717 | H18: =SUMIFS(Piutang!$F$2:$F$1751,Piutang!$B$2:$B$1751,">="&G18,Piutang!$B$2:$B$1751,"<"&EDATE(G18,1)) -> 1553507600 | I18: =SUMIFS(Piutang!$M$2:$M$1751,Piutang!$B$2:$B$1751,">="&G18,Piutang!$B$2:$B$1751,"<"&EDATE(G18,1)) -> 19677400
A19: SALES D | B19: =SUMIFS(Piutang!$F$2:$F$1751,Piutang!$E$2:$E$1751,A19) -> 4840842700 | C19: =SUMIFS(Piutang!$M$2:$M$1751,Piutang!$E$2:$E$1751,A19) -> 508003400 | D19: =C19-SUMIFS(Piutang!$M$2:$M$1751,Piutang!$E$2:$E$1751,A19,Piutang!$P$2:$P$1751,"Belum Jatuh Tempo") -> 208706400 | E19: =IF(C19=0,0,D19/C19) -> 0.41083662 | G19: 45748 | H19: =SUMIFS(Piutang!$F$2:$F$1751,Piutang!$B$2:$B$1751,">="&G19,Piutang!$B$2:$B$1751,"<"&EDATE(G19,1)) -> 1586180200 | I19: =SUMIFS(Piutang!$M$2:$M$1751,Piutang!$B$2:$B$1751,">="&G19,Piutang!$B$2:$B$1751,"<"&EDATE(G19,1)) -> 6842800
A20: KANTOR | B20: =SUMIFS(Piutang!$F$2:$F$1751,Piutang!$E$2:$E$1751,A20) -> 3797751000 | C20: =SUMIFS(Piutang!$M$2:$M$1751,Piutang!$E$2:$E$1751,A20) -> 0 | D20: =C20-SUMIFS(Piutang!$M$2:$M$1751,Piutang!$E$2:$E$1751,A20,Piutang!$P$2:$P$1751,"Belum Jatuh Tempo") -> 0 | E20: =IF(C20=0,0,D20/C20) -> 0 | G20: 45778 | H20: =SUMIFS(Piutang!$F$2:$F$1751,Piutang!$B$2:$B$1751,">="&G20,Piutang!$B$2:$B$1751,"<"&EDATE(G20,1)) -> 1709855800 | I20: =SUMIFS(Piutang!$M$2:$M$1751,Piutang!$B$2:$B$1751,">="&G20,Piutang!$B$2:$B$1751,"<"&EDATE(G20,1)) -> 34774200
A21: TOTAL | B21: =SUM(B16:B20) -> 18552147600 | C21: =SUM(C16:C20) -> 1208549400 | D21: =SUM(D16:D20) -> 470420300 | E21: =IF(C21=0,0,D21/C21) -> 0.38924375 | G21: 45809 | H21: =SUMIFS(Piutang!$F$2:$F$1751,Piutang!$B$2:$B$1751,">="&G21,Piutang!$B$2:$B$1751,"<"&EDATE(G21,1)) -> 1252767400 | I21: =SUMIFS(Piutang!$M$2:$M$1751,Piutang!$B$2:$B$1751,">="&G21,Piutang!$B$2:$B$1751,"<"&EDATE(G21,1)) -> 8448100
G22: 45839 | H22: =SUMIFS(Piutang!$F$2:$F$1751,Piutang!$B$2:$B$1751,">="&G22,Piutang!$B$2:$B$1751,"<"&EDATE(G22,1)) -> 1466421200 | I22: =SUMIFS(Piutang!$M$2:$M$1751,Piutang!$B$2:$B$1751,">="&G22,Piutang!$B$2:$B$1751,"<"&EDATE(G22,1)) -> 11168300
G23: 45870 | H23: =SUMIFS(Piutang!$F$2:$F$1751,Piutang!$B$2:$B$1751,">="&G23,Piutang!$B$2:$B$1751,"<"&EDATE(G23,1)) -> 1573166300 | I23: =SUMIFS(Piutang!$M$2:$M$1751,Piutang!$B$2:$B$1751,">="&G23,Piutang!$B$2:$B$1751,"<"&EDATE(G23,1)) -> 10663500
A24: TOP 10 CUSTOMER DENGAN PIUTANG OVERDUE TERBESAR | G24: 45901 | H24: =SUMIFS(Piutang!$F$2:$F$1751,Piutang!$B$2:$B$1751,">="&G24,Piutang!$B$2:$B$1751,"<"&EDATE(G24,1)) -> 1622212200 | I24: =SUMIFS(Piutang!$M$2:$M$1751,Piutang!$B$2:$B$1751,">="&G24,Piutang!$B$2:$B$1751,"<"&EDATE(G24,1)) -> 15484200
A25: Peringkat | B25: Nama Customer | C25: Total Piutang (Rp) | D25: Overdue (Rp) | E25: 90+ hari (Rp) | G25: 45931 | H25: =SUMIFS(Piutang!$F$2:$F$1751,Piutang!$B$2:$B$1751,">="&G25,Piutang!$B$2:$B$1751,"<"&EDATE(G25,1)) -> 1625867200 | I25: =SUMIFS(Piutang!$M$2:$M$1751,Piutang!$B$2:$B$1751,">="&G25,Piutang!$B$2:$B$1751,"<"&EDATE(G25,1)) -> 77501600
A26: 1 | B26: =INDEX(Aging_Customer!$B$2:$B$126,MATCH(D26,Aging_Customer!$J$2:$J$126,0)) -> SINAR AUTO BERKAH | C26: =INDEX(Aging_Customer!$D$2:$D$126,MATCH(D26,Aging_Customer!$J$2:$J$126,0)) -> 54601400 | D26: =LARGE(Aging_Customer!$J$2:$J$126,A26) -> 50123700 | E26: =INDEX(Aging_Customer!$I$2:$I$126,MATCH(D26,Aging_Customer!$J$2:$J$126,0)) -> 8448100 | G26: 45962 | H26: =SUMIFS(Piutang!$F$2:$F$1751,Piutang!$B$2:$B$1751,">="&G26,Piutang!$B$2:$B$1751,"<"&EDATE(G26,1)) -> 1411780600 | I26: =SUMIFS(Piutang!$M$2:$M$1751,Piutang!$B$2:$B$1751,">="&G26,Piutang!$B$2:$B$1751,"<"&EDATE(G26,1)) -> 246459400
A27: 2 | B27: =INDEX(Aging_Customer!$B$2:$B$126,MATCH(D27,Aging_Customer!$J$2:$J$126,0)) -> SUMBER TEKNIK SURYA | C27: =INDEX(Aging_Customer!$D$2:$D$126,MATCH(D27,Aging_Customer!$J$2:$J$126,0)) -> 183313200 | D27: =LARGE(Aging_Customer!$J$2:$J$126,A27) -> 34440900 | E27: =INDEX(Aging_Customer!$I$2:$I$126,MATCH(D27,Aging_Customer!$J$2:$J$126,0)) -> 30765100 | G27: 45992 | H27: =SUMIFS(Piutang!$F$2:$F$1751,Piutang!$B$2:$B$1751,">="&G27,Piutang!$B$2:$B$1751,"<"&EDATE(G27,1)) -> 1648383600 | I27: =SUMIFS(Piutang!$M$2:$M$1751,Piutang!$B$2:$B$1751,">="&G27,Piutang!$B$2:$B$1751,"<"&EDATE(G27,1)) -> 728475100
A28: 3 | B28: =INDEX(Aging_Customer!$B$2:$B$126,MATCH(D28,Aging_Customer!$J$2:$J$126,0)) -> LANCAR GARAGE UTAMA | C28: =INDEX(Aging_Customer!$D$2:$D$126,MATCH(D28,Aging_Customer!$J$2:$J$126,0)) -> 40914700 | D28: =LARGE(Aging_Customer!$J$2:$J$126,A28) -> 34057500 | E28: =INDEX(Aging_Customer!$I$2:$I$126,MATCH(D28,Aging_Customer!$J$2:$J$126,0)) -> 0 | G28: TOTAL | H28: =SUM(H16:H27) -> 18552147600 | I28: =SUM(I16:I27) -> 1208549400
A29: 4 | B29: =INDEX(Aging_Customer!$B$2:$B$126,MATCH(D29,Aging_Customer!$J$2:$J$126,0)) -> ABADI AUTO UTAMA | C29: =INDEX(Aging_Customer!$D$2:$D$126,MATCH(D29,Aging_Customer!$J$2:$J$126,0)) -> 31764600 | D29: =LARGE(Aging_Customer!$J$2:$J$126,A29) -> 25987400 | E29: =INDEX(Aging_Customer!$I$2:$I$126,MATCH(D29,Aging_Customer!$J$2:$J$126,0)) -> 0
A30: 5 | B30: =INDEX(Aging_Customer!$B$2:$B$126,MATCH(D30,Aging_Customer!$J$2:$J$126,0)) -> BINTANG OLI | C30: =INDEX(Aging_Customer!$D$2:$D$126,MATCH(D30,Aging_Customer!$J$2:$J$126,0)) -> 43609000 | D30: =LARGE(Aging_Customer!$J$2:$J$126,A30) -> 21381000 | E30: =INDEX(Aging_Customer!$I$2:$I$126,MATCH(D30,Aging_Customer!$J$2:$J$126,0)) -> 0
A31: 6 | B31: =INDEX(Aging_Customer!$B$2:$B$126,MATCH(D31,Aging_Customer!$J$2:$J$126,0)) -> BERKAH SPAREPART | C31: =INDEX(Aging_Customer!$D$2:$D$126,MATCH(D31,Aging_Customer!$J$2:$J$126,0)) -> 21754200 | D31: =LARGE(Aging_Customer!$J$2:$J$126,A31) -> 19540200 | E31: =INDEX(Aging_Customer!$I$2:$I$126,MATCH(D31,Aging_Customer!$J$2:$J$126,0)) -> 0
A32: 7 | B32: =INDEX(Aging_Customer!$B$2:$B$126,MATCH(D32,Aging_Customer!$J$2:$J$126,0)) -> MITRA GARAGE MULIA | C32: =INDEX(Aging_Customer!$D$2:$D$126,MATCH(D32,Aging_Customer!$J$2:$J$126,0)) -> 17735600 | D32: =LARGE(Aging_Customer!$J$2:$J$126,A32) -> 17735600 | E32: =INDEX(Aging_Customer!$I$2:$I$126,MATCH(D32,Aging_Customer!$J$2:$J$126,0)) -> 4069400
A33: 8 | B33: =INDEX(Aging_Customer!$B$2:$B$126,MATCH(D33,Aging_Customer!$J$2:$J$126,0)) -> BINTANG BENGKEL | C33: =INDEX(Aging_Customer!$D$2:$D$126,MATCH(D33,Aging_Customer!$J$2:$J$126,0)) -> 16598500 | D33: =LARGE(Aging_Customer!$J$2:$J$126,A33) -> 16598500 | E33: =INDEX(Aging_Customer!$I$2:$I$126,MATCH(D33,Aging_Customer!$J$2:$J$126,0)) -> 0
A34: 9 | B34: =INDEX(Aging_Customer!$B$2:$B$126,MATCH(D34,Aging_Customer!$J$2:$J$126,0)) -> MULIA BENGKEL UTAMA | C34: =INDEX(Aging_Customer!$D$2:$D$126,MATCH(D34,Aging_Customer!$J$2:$J$126,0)) -> 16281200 | D34: =LARGE(Aging_Customer!$J$2:$J$126,A34) -> 16281200 | E34: =INDEX(Aging_Customer!$I$2:$I$126,MATCH(D34,Aging_Customer!$J$2:$J$126,0)) -> 0
A35: 10 | B35: =INDEX(Aging_Customer!$B$2:$B$126,MATCH(D35,Aging_Customer!$J$2:$J$126,0)) -> BERKAH MOBIL MAKMUR | C35: =INDEX(Aging_Customer!$D$2:$D$126,MATCH(D35,Aging_Customer!$J$2:$J$126,0)) -> 16047200 | D35: =LARGE(Aging_Customer!$J$2:$J$126,A35) -> 16047200 | E35: =INDEX(Aging_Customer!$I$2:$I$126,MATCH(D35,Aging_Customer!$J$2:$J$126,0)) -> 16047200

Sheet Laporan_Piutang
A1: LAPORAN PIUTANG USAHA
A2: ="Posisi per "&TEXT(Catatan!B3,"dd mmmm yyyy") -> Posisi per 31 December 2025
A3: Disusun dari data penjualan sintetis (fiktif) Jan-Des 2025 untuk keperluan portofolio.
A5: A. RINGKASAN PIUTANG
B6: Total penjualan periode Jan-Des 2025 (Rp) | C6: =SUM(Piutang!F2:F1751) -> 18552147600
B7: Total piutang outstanding (Rp) | C7: =SUM(Piutang!M2:M1751) -> 1208549400
B8: Piutang sudah jatuh tempo / overdue (Rp) | C8: =Aging_Customer!J127 -> 470420300
B9: Persentase overdue terhadap piutang | C9: =IF(C7=0,0,C8/C7) -> 0.38924375
B10: Piutang lebih dari 90 hari (Rp) | C10: =Aging_Customer!I127 -> 144866300
B11: Perkiraan DSO (hari) | C11: =IF(C6=0,0,C7/C6*365) -> 23.77733
B12: Jumlah faktur belum lunas | C12: =COUNTIF(Piutang!M2:M1751,">0") -> 149
B13: Jumlah customer berpiutang | C13: =COUNTIF(Aging_Customer!D2:D126,">0") -> 66
A15: B. UMUR PIUTANG (AGING)
B16: Kategori | C16: Jumlah Faktur | D16: Sisa Piutang (Rp) | E16: % dari Total
B17: Belum Jatuh Tempo | C17: =COUNTIFS(Piutang!$P$2:$P$1751,B17,Piutang!$M$2:$M$1751,">0") -> 82 | D17: =SUMIFS(Piutang!$M$2:$M$1751,Piutang!$P$2:$P$1751,B17) -> 738129100 | E17: =IF($D$22=0,0,D17/$D$22) -> 0.61075625
B18: 1-30 hari | C18: =COUNTIFS(Piutang!$P$2:$P$1751,B18,Piutang!$M$2:$M$1751,">0") -> 26 | D18: =SUMIFS(Piutang!$M$2:$M$1751,Piutang!$P$2:$P$1751,B18) -> 204807200 | E18: =IF($D$22=0,0,D18/$D$22) -> 0.16946531
B19: 31-60 hari | C19: =COUNTIFS(Piutang!$P$2:$P$1751,B19,Piutang!$M$2:$M$1751,">0") -> 10 | D19: =SUMIFS(Piutang!$M$2:$M$1751,Piutang!$P$2:$P$1751,B19) -> 91756900 | E19: =IF($D$22=0,0,D19/$D$22) -> 0.075923169
B20: 61-90 hari | C20: =COUNTIFS(Piutang!$P$2:$P$1751,B20,Piutang!$M$2:$M$1751,">0") -> 5 | D20: =SUMIFS(Piutang!$M$2:$M$1751,Piutang!$P$2:$P$1751,B20) -> 28989900 | E20: =IF($D$22=0,0,D20/$D$22) -> 0.023987352
B21: 90+ hari | C21: =COUNTIFS(Piutang!$P$2:$P$1751,B21,Piutang!$M$2:$M$1751,">0") -> 26 | D21: =SUMIFS(Piutang!$M$2:$M$1751,Piutang!$P$2:$P$1751,B21) -> 144866300 | E21: =IF($D$22=0,0,D21/$D$22) -> 0.11986792
B22: TOTAL | C22: =SUM(C17:C21) -> 149 | D22: =SUM(D17:D21) -> 1208549400 | E22: =SUM(E17:E21) -> 1
A24: C. RINCIAN PIUTANG 25 CUSTOMER TERBESAR
A25: No | B25: Nama Customer | C25: Termin (hari) | D25: Belum Jatuh Tempo | E25: 1-30 hari | F25: 31-60 hari | G25: 61-90 hari | H25: 90+ hari | I25: Total Piutang (Rp) | J25: % Overdue | L25: helper
A26: 1 | B26: =IF($L26="","",INDEX(Aging_Customer!$B$2:$B$126,$L26)) -> SUMBER TEKNIK SURYA | C26: =IF($L26="","",INDEX(Aging_Customer!$C$2:$C$126,$L26)) -> 30 | D26: =IF($L26="","",INDEX(Aging_Customer!$E$2:$E$126,$L26)) -> 148872300 | E26: =IF($L26="","",INDEX(Aging_Customer!$F$2:$F$126,$L26)) -> 0 | F26: =IF($L26="","",INDEX(Aging_Customer!$G$2:$G$126,$L26)) -> 0 | G26: =IF($L26="","",INDEX(Aging_Customer!$H$2:$H$126,$L26)) -> 3675800 | H26: =IF($L26="","",INDEX(Aging_Customer!$I$2:$I$126,$L26)) -> 30765100 | I26: =IF($L26="","",INDEX(Aging_Customer!$D$2:$D$126,$L26)) -> 183313200 | J26: =IF($L26="","",INDEX(Aging_Customer!$K$2:$K$126,$L26)) -> 0.18788009 | L26: =IFERROR(MATCH(LARGE(Aging_Customer!$D$2:$D$126,A26),Aging_Customer!$D$2:$D$126,0),"") -> 1
A27: 2 | B27: =IF($L27="","",INDEX(Aging_Customer!$B$2:$B$126,$L27)) -> SUMBER OLI GEMILANG | C27: =IF($L27="","",INDEX(Aging_Customer!$C$2:$C$126,$L27)) -> 30 | D27: =IF($L27="","",INDEX(Aging_Customer!$E$2:$E$126,$L27)) -> 51770600 | E27: =IF($L27="","",INDEX(Aging_Customer!$F$2:$F$126,$L27)) -> 9088100 | F27: =IF($L27="","",INDEX(Aging_Customer!$G$2:$G$126,$L27)) -> 0 | G27: =IF($L27="","",INDEX(Aging_Customer!$H$2:$H$126,$L27)) -> 0 | H27: =IF($L27="","",INDEX(Aging_Customer!$I$2:$I$126,$L27)) -> 0 | I27: =IF($L27="","",INDEX(Aging_Customer!$D$2:$D$126,$L27)) -> 60858700 | J27: =IF($L27="","",INDEX(Aging_Customer!$K$2:$K$126,$L27)) -> 0.14933116 | L27: =IFERROR(MATCH(LARGE(Aging_Customer!$D$2:$D$126,A27),Aging_Customer!$D$2:$D$126,0),"") -> 2
A28: 3 | B28: =IF($L28="","",INDEX(Aging_Customer!$B$2:$B$126,$L28)) -> MAJU GARAGE TIRTA | C28: =IF($L28="","",INDEX(Aging_Customer!$C$2:$C$126,$L28)) -> 45 | D28: =IF($L28="","",INDEX(Aging_Customer!$E$2:$E$126,$L28)) -> 51794600 | E28: =IF($L28="","",INDEX(Aging_Customer!$F$2:$F$126,$L28)) -> 0 | F28: =IF($L28="","",INDEX(Aging_Customer!$G$2:$G$126,$L28)) -> 0 | G28: =IF($L28="","",INDEX(Aging_Customer!$H$2:$H$126,$L28)) -> 0 | H28: =IF($L28="","",INDEX(Aging_Customer!$I$2:$I$126,$L28)) -> 4412400 | I28: =IF($L28="","",INDEX(Aging_Customer!$D$2:$D$126,$L28)) -> 56207000 | J28: =IF($L28="","",INDEX(Aging_Customer!$K$2:$K$126,$L28)) -> 0.078502678 | L28: =IFERROR(MATCH(LARGE(Aging_Customer!$D$2:$D$126,A28),Aging_Customer!$D$2:$D$126,0),"") -> 3
A29: 4 | B29: =IF($L29="","",INDEX(Aging_Customer!$B$2:$B$126,$L29)) -> SINAR AUTO BERKAH | C29: =IF($L29="","",INDEX(Aging_Customer!$C$2:$C$126,$L29)) -> 30 | D29: =IF($L29="","",INDEX(Aging_Customer!$E$2:$E$126,$L29)) -> 4477700 | E29: =IF($L29="","",INDEX(Aging_Customer!$F$2:$F$126,$L29)) -> 27854000 | F29: =IF($L29="","",INDEX(Aging_Customer!$G$2:$G$126,$L29)) -> 13821600 | G29: =IF($L29="","",INDEX(Aging_Customer!$H$2:$H$126,$L29)) -> 0 | H29: =IF($L29="","",INDEX(Aging_Customer!$I$2:$I$126,$L29)) -> 8448100 | I29: =IF($L29="","",INDEX(Aging_Customer!$D$2:$D$126,$L29)) -> 54601400 | J29: =IF($L29="","",INDEX(Aging_Customer!$K$2:$K$126,$L29)) -> 0.91799295 | L29: =IFERROR(MATCH(LARGE(Aging_Customer!$D$2:$D$126,A29),Aging_Customer!$D$2:$D$126,0),"") -> 4
A30: 5 | B30: =IF($L30="","",INDEX(Aging_Customer!$B$2:$B$126,$L30)) -> KARYA SPAREPART | C30: =IF($L30="","",INDEX(Aging_Customer!$C$2:$C$126,$L30)) -> 45 | D30: =IF($L30="","",INDEX(Aging_Customer!$E$2:$E$126,$L30)) -> 48877600 | E30: =IF($L30="","",INDEX(Aging_Customer!$F$2:$F$126,$L30)) -> 1215900 | F30: =IF($L30="","",INDEX(Aging_Customer!$G$2:$G$126,$L30)) -> 1316300 | G30: =IF($L30="","",INDEX(Aging_Customer!$H$2:$H$126,$L30)) -> 0 | H30: =IF($L30="","",INDEX(Aging_Customer!$I$2:$I$126,$L30)) -> 1732600 | I30: =IF($L30="","",INDEX(Aging_Customer!$D$2:$D$126,$L30)) -> 53142400 | J30: =IF($L30="","",INDEX(Aging_Customer!$K$2:$K$126,$L30)) -> 0.080252303 | L30: =IFERROR(MATCH(LARGE(Aging_Customer!$D$2:$D$126,A30),Aging_Customer!$D$2:$D$126,0),"") -> 5
A31: 6 | B31: =IF($L31="","",INDEX(Aging_Customer!$B$2:$B$126,$L31)) -> BINTANG OLI | C31: =IF($L31="","",INDEX(Aging_Customer!$C$2:$C$126,$L31)) -> 14 | D31: =IF($L31="","",INDEX(Aging_Customer!$E$2:$E$126,$L31)) -> 22228000 | E31: =IF($L31="","",INDEX(Aging_Customer!$F$2:$F$126,$L31)) -> 21381000 | F31: =IF($L31="","",INDEX(Aging_Customer!$G$2:$G$126,$L31)) -> 0 | G31: =IF($L31="","",INDEX(Aging_Customer!$H$2:$H$126,$L31)) -> 0 | H31: =IF($L31="","",INDEX(Aging_Customer!$I$2:$I$126,$L31)) -> 0 | I31: =IF($L31="","",INDEX(Aging_Customer!$D$2:$D$126,$L31)) -> 43609000 | J31: =IF($L31="","",INDEX(Aging_Customer!$K$2:$K$126,$L31)) -> 0.4902887 | L31: =IFERROR(MATCH(LARGE(Aging_Customer!$D$2:$D$126,A31),Aging_Customer!$D$2:$D$126,0),"") -> 6
A32: 7 | B32: =IF($L32="","",INDEX(Aging_Customer!$B$2:$B$126,$L32)) -> LANCAR GARAGE UTAMA | C32: =IF($L32="","",INDEX(Aging_Customer!$C$2:$C$126,$L32)) -> 14 | D32: =IF($L32="","",INDEX(Aging_Customer!$E$2:$E$126,$L32)) -> 6857200 | E32: =IF($L32="","",INDEX(Aging_Customer!$F$2:$F$126,$L32)) -> 17519100 | F32: =IF($L32="","",INDEX(Aging_Customer!$G$2:$G$126,$L32)) -> 16538400 | G32: =IF($L32="","",INDEX(Aging_Customer!$H$2:$H$126,$L32)) -> 0 | H32: =IF($L32="","",INDEX(Aging_Customer!$I$2:$I$126,$L32)) -> 0 | I32: =IF($L32="","",INDEX(Aging_Customer!$D$2:$D$126,$L32)) -> 40914700 | J32: =IF($L32="","",INDEX(Aging_Customer!$K$2:$K$126,$L32)) -> 0.83240254 | L32: =IFERROR(MATCH(LARGE(Aging_Customer!$D$2:$D$126,A32),Aging_Customer!$D$2:$D$126,0),"") -> 7
A33: 8 | B33: =IF($L33="","",INDEX(Aging_Customer!$B$2:$B$126,$L33)) -> HARAPAN MOTOR | C33: =IF($L33="","",INDEX(Aging_Customer!$C$2:$C$126,$L33)) -> 45 | D33: =IF($L33="","",INDEX(Aging_Customer!$E$2:$E$126,$L33)) -> 24083500 | E33: =IF($L33="","",INDEX(Aging_Customer!$F$2:$F$126,$L33)) -> 0 | F33: =IF($L33="","",INDEX(Aging_Customer!$G$2:$G$126,$L33)) -> 0 | G33: =IF($L33="","",INDEX(Aging_Customer!$H$2:$H$126,$L33)) -> 0 | H33: =IF($L33="","",INDEX(Aging_Customer!$I$2:$I$126,$L33)) -> 11783000 | I33: =IF($L33="","",INDEX(Aging_Customer!$D$2:$D$126,$L33)) -> 35866500 | J33: =IF($L33="","",INDEX(Aging_Customer!$K$2:$K$126,$L33)) -> 0.32852383 | L33: =IFERROR(MATCH(LARGE(Aging_Customer!$D$2:$D$126,A33),Aging_Customer!$D$2:$D$126,0),"") -> 8
A34: 9 | B34: =IF($L34="","",INDEX(Aging_Customer!$B$2:$B$126,$L34)) -> ABADI AUTO UTAMA | C34: =IF($L34="","",INDEX(Aging_Customer!$C$2:$C$126,$L34)) -> 14 | D34: =IF($L34="","",INDEX(Aging_Customer!$E$2:$E$126,$L34)) -> 5777200 | E34: =IF($L34="","",INDEX(Aging_Customer!$F$2:$F$126,$L34)) -> 25987400 | F34: =IF($L34="","",INDEX(Aging_Customer!$G$2:$G$126,$L34)) -> 0 | G34: =IF($L34="","",INDEX(Aging_Customer!$H$2:$H$126,$L34)) -> 0 | H34: =IF($L34="","",INDEX(Aging_Customer!$I$2:$I$126,$L34)) -> 0 | I34: =IF($L34="","",INDEX(Aging_Customer!$D$2:$D$126,$L34)) -> 31764600 | J34: =IF($L34="","",INDEX(Aging_Customer!$K$2:$K$126,$L34)) -> 0.81812458 | L34: =IFERROR(MATCH(LARGE(Aging_Customer!$D$2:$D$126,A34),Aging_Customer!$D$2:$D$126,0),"") -> 9
A35: 10 | B35: =IF($L35="","",INDEX(Aging_Customer!$B$2:$B$126,$L35)) -> CAHAYA OLI | C35: =IF($L35="","",INDEX(Aging_Customer!$C$2:$C$126,$L35)) -> 30 | D35: =IF($L35="","",INDEX(Aging_Customer!$E$2:$E$126,$L35)) -> 20966300 | E35: =IF($L35="","",INDEX(Aging_Customer!$F$2:$F$126,$L35)) -> 8670700 | F35: =IF($L35="","",INDEX(Aging_Customer!$G$2:$G$126,$L35)) -> 0 | G35: =IF($L35="","",INDEX(Aging_Customer!$H$2:$H$126,$L35)) -> 0 | H35: =IF($L35="","",INDEX(Aging_Customer!$I$2:$I$126,$L35)) -> 1948100 | I35: =IF($L35="","",INDEX(Aging_Customer!$D$2:$D$126,$L35)) -> 31585100 | J35: =IF($L35="","",INDEX(Aging_Customer!$K$2:$K$126,$L35)) -> 0.3361965 | L35: =IFERROR(MATCH(LARGE(Aging_Customer!$D$2:$D$126,A35),Aging_Customer!$D$2:$D$126,0),"") -> 10
A36: 11 | B36: =IF($L36="","",INDEX(Aging_Customer!$B$2:$B$126,$L36)) -> SINAR GARAGE | C36: =IF($L36="","",INDEX(Aging_Customer!$C$2:$C$126,$L36)) -> 30 | D36: =IF($L36="","",INDEX(Aging_Customer!$E$2:$E$126,$L36)) -> 23762500 | E36: =IF($L36="","",INDEX(Aging_Customer!$F$2:$F$126,$L36)) -> 0 | F36: =IF($L36="","",INDEX(Aging_Customer!$G$2:$G$126,$L36)) -> 0 | G36: =IF($L36="","",INDEX(Aging_Customer!$H$2:$H$126,$L36)) -> 0 | H36: =IF($L36="","",INDEX(Aging_Customer!$I$2:$I$126,$L36)) -> 1529700 | I36: =IF($L36="","",INDEX(Aging_Customer!$D$2:$D$126,$L36)) -> 25292200 | J36: =IF($L36="","",INDEX(Aging_Customer!$K$2:$K$126,$L36)) -> 0.060481097 | L36: =IFERROR(MATCH(LARGE(Aging_Customer!$D$2:$D$126,A36),Aging_Customer!$D$2:$D$126,0),"") -> 11
A37: 12 | B37: =IF($L37="","",INDEX(Aging_Customer!$B$2:$B$126,$L37)) -> MAKMUR AUTO HARAPAN | C37: =IF($L37="","",INDEX(Aging_Customer!$C$2:$C$126,$L37)) -> 30 | D37: =IF($L37="","",INDEX(Aging_Customer!$E$2:$E$126,$L37)) -> 22546700 | E37: =IF($L37="","",INDEX(Aging_Customer!$F$2:$F$126,$L37)) -> 0 | F37: =IF($L37="","",INDEX(Aging_Customer!$G$2:$G$126,$L37)) -> 0 | G37: =IF($L37="","",INDEX(Aging_Customer!$H$2:$H$126,$L37)) -> 0 | H37: =IF($L37="","",INDEX(Aging_Customer!$I$2:$I$126,$L37)) -> 0 | I37: =IF($L37="","",INDEX(Aging_Customer!$D$2:$D$126,$L37)) -> 22546700 | J37: =IF($L37="","",INDEX(Aging_Customer!$K$2:$K$126,$L37)) -> 0 | L37: =IFERROR(MATCH(LARGE(Aging_Customer!$D$2:$D$126,A37),Aging_Customer!$D$2:$D$126,0),"") -> 12
... A50: 25 | B50: =IF($L50="","",INDEX(Aging_Customer!$B$2:$B$126,$L50)) -> MITRA BENGKEL | C50: =IF($L50="","",INDEX(Aging_Customer!$C$2:$C$126,$L50)) -> 30 | D50: =IF($L50="","",INDEX(Aging_Customer!$E$2:$E$126,$L50)) -> 0 | E50: =IF($L50="","",INDEX(Aging_Customer!$F$2:$F$126,$L50)) -> 0 | F50: =IF($L50="","",INDEX(Aging_Customer!$G$2:$G$126,$L50)) -> 0 | G50: =IF($L50="","",INDEX(Aging_Customer!$H$2:$H$126,$L50)) -> 7080600 | H50: =IF($L50="","",INDEX(Aging_Customer!$I$2:$I$126,$L50)) -> 8904800 | I50: =IF($L50="","",INDEX(Aging_Customer!$D$2:$D$126,$L50)) -> 15985400 | J50: =IF($L50="","",INDEX(Aging_Customer!$K$2:$K$126,$L50)) -> 1 | L50: =IFERROR(MATCH(LARGE(Aging_Customer!$D$2:$D$126,A50),Aging_Customer!$D$2:$D$126,0),"") -> 25
B51: Customer lainnya | D51: =Aging_Customer!E127-SUM(D26:D50) -> 200870700 | E51: =Aging_Customer!F127-SUM(E26:E50) -> 50720200 | F51: =Aging_Customer!G127-SUM(F26:F50) -> 16310900 | G51: =Aging_Customer!H127-SUM(G26:G50) -> 6254900 | H51: =Aging_Customer!I127-SUM(H26:H50) -> 53208800 | I51: =Aging_Customer!D127-SUM(I26:I50) -> 327365500 | J51: =IF(I51=0,0,SUM(E51:H51)/I51) -> 0.38640235
B52: TOTAL PIUTANG | D52: =SUM(D26:D51) -> 738129100 | E52: =SUM(E26:E51) -> 204807200 | F52: =SUM(F26:F51) -> 91756900 | G52: =SUM(G26:G51) -> 28989900 | H52: =SUM(H26:H51) -> 144866300 | I52: =SUM(I26:I51) -> 1208549400 | J52: =IF(I52=0,0,SUM(E52:H52)/I52) -> 0.38924375
A54: D. CATATAN ANALISIS & REKOMENDASI TINDAK LANJUT
B55: ="1. Piutang outstanding sebesar Rp "&TEXT(C7,"#,##0")&" ("&TEXT(IF(C6=0,0,C7/C6),"0.0%")&" dari penjualan), dengan "&TEXT(C9,"0.0%")&" di antaranya sudah melewati jatuh tempo." -> 1. Piutang outstanding sebesar Rp 1,208,549,400 (6.5% dari penjualan), dengan 38.9% di antaranya sudah melewati jatuh tempo.
B56: ="2. Piutang di atas 90 hari mencapai Rp "&TEXT(C10,"#,##0")&"; perlu eskalasi ke supervisor dan evaluasi pembatasan pengiriman." -> 2. Piutang di atas 90 hari mencapai Rp 144,866,300; perlu eskalasi ke supervisor dan evaluasi pembatasan pengiriman.
...

Sheet Laporan_Faktur
A1: LAPORAN FAKTUR PENJUALAN
A2: ="Posisi per "&TEXT(Catatan!B3,"dd mmmm yyyy") -> Posisi per 31 December 2025
A3: Rekap faktur berdasarkan status pembayaran, status tukar faktur, bulan faktur, dan jadwal jatuh tempo.
A5: A. STATUS PEMBAYARAN FAKTUR
B6: Status | C6: Jumlah Faktur | D6: Nominal Faktur (Rp) | E6: Dibayar (Rp) | F6: Sisa Piutang (Rp) | G6: % Faktur
B7: Lunas | C7: =COUNTIF(Piutang!$N$2:$N$1751,B7) -> 1601 | D7: =SUMIFS(Piutang!$F$2:$F$1751,Piutang!$N$2:$N$1751,$B7) -> 17075612800 | E7: =SUMIFS(Piutang!$K$2:$K$1751,Piutang!$N$2:$N$1751,$B7) -> 17075612800 | F7: =SUMIFS(Piutang!$M$2:$M$1751,Piutang!$N$2:$N$1751,$B7) -> 0 | G7: =IF($C$10=0,0,C7/$C$10) -> 0.91485714
B8: Sebagian | C8: =COUNTIF(Piutang!$N$2:$N$1751,B8) -> 53 | D8: =SUMIFS(Piutang!$F$2:$F$1751,Piutang!$N$2:$N$1751,$B8) -> 505085700 | E8: =SUMIFS(Piutang!$K$2:$K$1751,Piutang!$N$2:$N$1751,$B8) -> 267985400 | F8: =SUMIFS(Piutang!$M$2:$M$1751,Piutang!$N$2:$N$1751,$B8) -> 237100300 | G8: =IF($C$10=0,0,C8/$C$10) -> 0.030285714
B9: Belum Bayar | C9: =COUNTIF(Piutang!$N$2:$N$1751,B9) -> 96 | D9: =SUMIFS(Piutang!$F$2:$F$1751,Piutang!$N$2:$N$1751,$B9) -> 971449100 | E9: =SUMIFS(Piutang!$K$2:$K$1751,Piutang!$N$2:$N$1751,$B9) -> 0 | F9: =SUMIFS(Piutang!$M$2:$M$1751,Piutang!$N$2:$N$1751,$B9) -> 971449100 | G9: =IF($C$10=0,0,C9/$C$10) -> 0.054857143
B10: TOTAL | C10: =SUM(C7:C9) -> 1750 | D10: =SUM(D7:D9) -> 18552147600 | E10: =SUM(E7:E9) -> 17343598200 | F10: =SUM(F7:F9) -> 1208549400 | G10: =SUM(G7:G9) -> 1
A12: B. STATUS TUKAR FAKTUR
B13: Status | C13: Jumlah Faktur | D13: Nominal Faktur (Rp) | E13: Sisa Piutang (Rp)
B14: Tunai | C14: =COUNTIF(Piutang!$J$2:$J$1751,B14) -> 680 | D14: =SUMIFS(Piutang!$F$2:$F$1751,Piutang!$J$2:$J$1751,$B14) -> 6917285800 | E14: =SUMIFS(Piutang!$M$2:$M$1751,Piutang!$J$2:$J$1751,$B14) -> 3048800
B15: Sudah ditukar | C15: =COUNTIF(Piutang!$J$2:$J$1751,B15) -> 1061 | D15: =SUMIFS(Piutang!$F$2:$F$1751,Piutang!$J$2:$J$1751,$B15) -> 11560823000 | E15: =SUMIFS(Piutang!$M$2:$M$1751,Piutang!$J$2:$J$1751,$B15) -> 1139680700
B16: Belum ditukar | C16: =COUNTIF(Piutang!$J$2:$J$1751,B16) -> 9 | D16: =SUMIFS(Piutang!$F$2:$F$1751,Piutang!$J$2:$J$1751,$B16) -> 74038800 | E16: =SUMIFS(Piutang!$M$2:$M$1751,Piutang!$J$2:$J$1751,$B16) -> 65819900
B17: TOTAL | C17: =SUM(C14:C16) -> 1750 | D17: =SUM(D14:D16) -> 18552147600 | E17: =SUM(E14:E16) -> 1208549400
A19: C. REKAP FAKTUR PER BULAN
B20: Bulan | C20: Jumlah Faktur | D20: Nominal Faktur (Rp) | E20: Dibayar (Rp) | F20: Sisa Piutang (Rp) | G20: % Terbayar
B21: 45658 | C21: =COUNTIFS(Piutang!$B$2:$B$1751,">="&$B21,Piutang!$B$2:$B$1751,"<"&EDATE($B21,1)) -> 140 | D21: =SUMIFS(Piutang!$F$2:$F$1751,Piutang!$B$2:$B$1751,">="&$B21,Piutang!$B$2:$B$1751,"<"&EDATE($B21,1)) -> 1576054400 | E21: =SUMIFS(Piutang!$K$2:$K$1751,Piutang!$B$2:$B$1751,">="&$B21,Piutang!$B$2:$B$1751,"<"&EDATE($B21,1)) -> 1566693600 | F21: =SUMIFS(Piutang!$M$2:$M$1751,Piutang!$B$2:$B$1751,">="&$B21,Piutang!$B$2:$B$1751,"<"&EDATE($B21,1)) -> 9360800 | G21: =IF(D21=0,0,E21/D21) -> 0.99406061
B22: 45689 | C22: =COUNTIFS(Piutang!$B$2:$B$1751,">="&$B22,Piutang!$B$2:$B$1751,"<"&EDATE($B22,1)) -> 134 | D22: =SUMIFS(Piutang!$F$2:$F$1751,Piutang!$B$2:$B$1751,">="&$B22,Piutang!$B$2:$B$1751,"<"&EDATE($B22,1)) -> 1525951100 | E22: =SUMIFS(Piutang!$K$2:$K$1751,Piutang!$B$2:$B$1751,">="&$B22,Piutang!$B$2:$B$1751,"<"&EDATE($B22,1)) -> 1486257100 | F22: =SUMIFS(Piutang!$M$2:$M$1751,Piutang!$B$2:$B$1751,">="&$B22,Piutang!$B$2:$B$1751,"<"&EDATE($B22,1)) -> 39694000 | G22: =IF(D22=0,0,E22/D22) -> 0.97398737
B23: 45717 | C23: =COUNTIFS(Piutang!$B$2:$B$1751,">="&$B23,Piutang!$B$2:$B$1751,"<"&EDATE($B23,1)) -> 138 | D23: =SUMIFS(Piutang!$F$2:$F$1751,Piutang!$B$2:$B$1751,">="&$B23,Piutang!$B$2:$B$1751,"<"&EDATE($B23,1)) -> 1553507600 | E23: =SUMIFS(Piutang!$K$2:$K$1751,Piutang!$B$2:$B$1751,">="&$B23,Piutang!$B$2:$B$1751,"<"&EDATE($B23,1)) -> 1533830200 | F23: =SUMIFS(Piutang!$M$2:$M$1751,Piutang!$B$2:$B$1751,">="&$B23,Piutang!$B$2:$B$1751,"<"&EDATE($B23,1)) -> 19677400 | G23: =IF(D23=0,0,E23/D23) -> 0.98733357
B24: 45748 | C24: =COUNTIFS(Piutang!$B$2:$B$1751,">="&$B24,Piutang!$B$2:$B$1751,"<"&EDATE($B24,1)) -> 144 | D24: =SUMIFS(Piutang!$F$2:$F$1751,Piutang!$B$2:$B$1751,">="&$B24,Piutang!$B$2:$B$1751,"<"&EDATE($B24,1)) -> 1586180200 | E24: =SUMIFS(Piutang!$K$2:$K$1751,Piutang!$B$2:$B$1751,">="&$B24,Piutang!$B$2:$B$1751,"<"&EDATE($B24,1)) -> 1579337400 | F24: =SUMIFS(Piutang!$M$2:$M$1751,Piutang!$B$2:$B$1751,">="&$B24,Piutang!$B$2:$B$1751,"<"&EDATE($B24,1)) -> 6842800 | G24: =IF(D24=0,0,E24/D24) -> 0.99568599
B25: 45778 | C25: =COUNTIFS(Piutang!$B$2:$B$1751,">="&$B25,Piutang!$B$2:$B$1751,"<"&EDATE($B25,1)) -> 158 | D25: =SUMIFS(Piutang!$F$2:$F$1751,Piutang!$B$2:$B$1751,">="&$B25,Piutang!$B$2:$B$1751,"<"&EDATE($B25,1)) -> 1709855800 | E25: =SUMIFS(Piutang!$K$2:$K$1751,Piutang!$B$2:$B$1751,">="&$B25,Piutang!$B$2:$B$1751,"<"&EDATE($B25,1)) -> 1675081600 | F25: =SUMIFS(Piutang!$M$2:$M$1751,Piutang!$B$2:$B$1751,">="&$B25,Piutang!$B$2:$B$1751,"<"&EDATE($B25,1)) -> 34774200 | G25: =IF(D25=0,0,E25/D25) -> 0.9796625
B26: 45809 | C26: =COUNTIFS(Piutang!$B$2:$B$1751,">="&$B26,Piutang!$B$2:$B$1751,"<"&EDATE($B26,1)) -> 125 | D26: =SUMIFS(Piutang!$F$2:$F$1751,Piutang!$B$2:$B$1751,">="&$B26,Piutang!$B$2:$B$1751,"<"&EDATE($B26,1)) -> 1252767400 | E26: =SUMIFS(Piutang!$K$2:$K$1751,Piutang!$B$2:$B$1751,">="&$B26,Piutang!$B$2:$B$1751,"<"&EDATE($B26,1)) -> 1244319300 | F26: =SUMIFS(Piutang!$M$2:$M$1751,Piutang!$B$2:$B$1751,">="&$B26,Piutang!$B$2:$B$1751,"<"&EDATE($B26,1)) -> 8448100 | G26: =IF(D26=0,0,E26/D26) -> 0.99325645
B27: 45839 | C27: =COUNTIFS(Piutang!$B$2:$B$1751,">="&$B27,Piutang!$B$2:$B$1751,"<"&EDATE($B27,1)) -> 152 | D27: =SUMIFS(Piutang!$F$2:$F$1751,Piutang!$B$2:$B$1751,">="&$B27,Piutang!$B$2:$B$1751,"<"&EDATE($B27,1)) -> 1466421200 | E27: =SUMIFS(Piutang!$K$2:$K$1751,Piutang!$B$2:$B$1751,">="&$B27,Piutang!$B$2:$B$1751,"<"&EDATE($B27,1)) -> 1455252900 | F27: =SUMIFS(Piutang!$M$2:$M$1751,Piutang!$B$2:$B$1751,">="&$B27,Piutang!$B$2:$B$1751,"<"&EDATE($B27,1)) -> 11168300 | G27: =IF(D27=0,0,E27/D27) -> 0.99238398
B28: 45870 | C28: =COUNTIFS(Piutang!$B$2:$B$1751,">="&$B28,Piutang!$B$2:$B$1751,"<"&EDATE($B28,1)) -> 153 | D28: =SUMIFS(Piutang!$F$2:$F$1751,Piutang!$B$2:$B$1751,">="&$B28,Piutang!$B$2:$B$1751,"<"&EDATE($B28,1)) -> 1573166300 | E28: =SUMIFS(Piutang!$K$2:$K$1751,Piutang!$B$2:$B$1751,">="&$B28,Piutang!$B$2:$B$1751,"<"&EDATE($B28,1)) -> 1562502800 | F28: =SUMIFS(Piutang!$M$2:$M$1751,Piutang!$B$2:$B$1751,">="&$B28,Piutang!$B$2:$B$1751,"<"&EDATE($B28,1)) -> 10663500 | G28: =IF(D28=0,0,E28/D28) -> 0.99322163
B29: 45901 | C29: =COUNTIFS(Piutang!$B$2:$B$1751,">="&$B29,Piutang!$B$2:$B$1751,"<"&EDATE($B29,1)) -> 143 | D29: =SUMIFS(Piutang!$F$2:$F$1751,Piutang!$B$2:$B$1751,">="&$B29,Piutang!$B$2:$B$1751,"<"&EDATE($B29,1)) -> 1622212200 | E29: =SUMIFS(Piutang!$K$2:$K$1751,Piutang!$B$2:$B$1751,">="&$B29,Piutang!$B$2:$B$1751,"<"&EDATE($B29,1)) -> 1606728000 | F29: =SUMIFS(Piutang!$M$2:$M$1751,Piutang!$B$2:$B$1751,">="&$B29,Piutang!$B$2:$B$1751,"<"&EDATE($B29,1)) -> 15484200 | G29: =IF(D29=0,0,E29/D29) -> 0.99045489
B30: 45931 | C30: =COUNTIFS(Piutang!$B$2:$B$1751,">="&$B30,Piutang!$B$2:$B$1751,"<"&EDATE($B30,1)) -> 159 | D30: =SUMIFS(Piutang!$F$2:$F$1751,Piutang!$B$2:$B$1751,">="&$B30,Piutang!$B$2:$B$1751,"<"&EDATE($B30,1)) -> 1625867200 | E30: =SUMIFS(Piutang!$K$2:$K$1751,Piutang!$B$2:$B$1751,">="&$B30,Piutang!$B$2:$B$1751,"<"&EDATE($B30,1)) -> 1548365600 | F30: =SUMIFS(Piutang!$M$2:$M$1751,Piutang!$B$2:$B$1751,">="&$B30,Piutang!$B$2:$B$1751,"<"&EDATE($B30,1)) -> 77501600 | G30: =IF(D30=0,0,E30/D30) -> 0.95233215
B31: 45962 | C31: =COUNTIFS(Piutang!$B$2:$B$1751,">="&$B31,Piutang!$B$2:$B$1751,"<"&EDATE($B31,1)) -> 140 | D31: =SUMIFS(Piutang!$F$2:$F$1751,Piutang!$B$2:$B$1751,">="&$B31,Piutang!$B$2:$B$1751,"<"&EDATE($B31,1)) -> 1411780600 | E31: =SUMIFS(Piutang!$K$2:$K$1751,Piutang!$B$2:$B$1751,">="&$B31,Piutang!$B$2:$B$1751,"<"&EDATE($B31,1)) -> 1165321200 | F31: =SUMIFS(Piutang!$M$2:$M$1751,Piutang!$B$2:$B$1751,">="&$B31,Piutang!$B$2:$B$1751,"<"&EDATE($B31,1)) -> 246459400 | G31: =IF(D31=0,0,E31/D31) -> 0.82542656
B32: 45992 | C32: =COUNTIFS(Piutang!$B$2:$B$1751,">="&$B32,Piutang!$B$2:$B$1751,"<"&EDATE($B32,1)) -> 164 | D32: =SUMIFS(Piutang!$F$2:$F$1751,Piutang!$B$2:$B$1751,">="&$B32,Piutang!$B$2:$B$1751,"<"&EDATE($B32,1)) -> 1648383600 | E32: =SUMIFS(Piutang!$K$2:$K$1751,Piutang!$B$2:$B$1751,">="&$B32,Piutang!$B$2:$B$1751,"<"&EDATE($B32,1)) -> 919908500 | F32: =SUMIFS(Piutang!$M$2:$M$1751,Piutang!$B$2:$B$1751,">="&$B32,Piutang!$B$2:$B$1751,"<"&EDATE($B32,1)) -> 728475100 | G32: =IF(D32=0,0,E32/D32) -> 0.55806701
B33: TOTAL | C33: =SUM(C21:C32) -> 1750 | D33: =SUM(D21:D32) -> 18552147600 | E33: =SUM(E21:E32) -> 17343598200 | F33: =SUM(F21:F32) -> 1208549400 | G33: =IF(D33=0,0,E33/D33) -> 0.93485663
A35: D. JADWAL JATUH TEMPO FAKTUR BELUM LUNAS (KE DEPAN)
B36: Jatuh tempo dalam | C36: Jumlah Faktur | D36: Sisa Piutang (Rp)
B37: 0-7 hari | C37: =COUNTIFS(Piutang!$M$2:$M$1751,">0",Piutang!$H$2:$H$1751,">="&(Catatan!$B$3+0),Piutang!$H$2:$H$1751,"<="&(Catatan!$B$3+7)) -> 17 | D37: =SUMIFS(Piutang!$M$2:$M$1751,Piutang!$M$2:$M$1751,">0",Piutang!$H$2:$H$1751,">="&(Catatan!$B$3+0),Piutang!$H$2:$H$1751,"<="&(Catatan!$B$3+7)) -> 135024800
B38: 8-14 hari | C38: =COUNTIFS(Piutang!$M$2:$M$1751,">0",Piutang!$H$2:$H$1751,">="&(Catatan!$B$3+8),Piutang!$H$2:$H$1751,"<="&(Catatan!$B$3+14)) -> 21 | D38: =SUMIFS(Piutang!$M$2:$M$1751,Piutang!$M$2:$M$1751,">0",Piutang!$H$2:$H$1751,">="&(Catatan!$B$3+8),Piutang!$H$2:$H$1751,"<="&(Catatan!$B$3+14)) -> 172676900
B39: 15-30 hari | C39: =COUNTIFS(Piutang!$M$2:$M$1751,">0",Piutang!$H$2:$H$1751,">="&(Catatan!$B$3+15),Piutang!$H$2:$H$1751,"<="&(Catatan!$B$3+30)) -> 30 | D39: =SUMIFS(Piutang!$M$2:$M$1751,Piutang!$M$2:$M$1751,">0",Piutang!$H$2:$H$1751,">="&(Catatan!$B$3+15),Piutang!$H$2:$H$1751,"<="&(Catatan!$B$3+30)) -> 328223200
B40: Lebih dari 30 hari | C40: =COUNTIFS(Piutang!$M$2:$M$1751,">0",Piutang!$H$2:$H$1751,">="&(Catatan!$B$3+31),Piutang!$H$2:$H$1751,"<="&(Catatan!$B$3+9999)) -> 14 | D40: =SUMIFS(Piutang!$M$2:$M$1751,Piutang!$M$2:$M$1751,">0",Piutang!$H$2:$H$1751,">="&(Catatan!$B$3+31),Piutang!$H$2:$H$1751,"<="&(Catatan!$B$3+9999)) -> 102204200
B41: TOTAL | C41: =SUM(C37:C40) -> 82 | D41: =SUM(D37:D40) -> 738129100
B42: Faktur yang sudah lewat jatuh tempo ada di Laporan_Piutang (aging).

Sheet Cetak_Faktur
A1: PT CONTOH DISTRIBUSI PELUMAS (DUMMY) | E1: FAKTUR PENJUALAN
A2: Alamat perusahaan contoh - Tangerang Selatan
A3: Pilih No. Faktur pada sel kuning; seluruh isi faktur terisi otomatis dari Data_Penjualan dan Piutang.
G4: helper
A5: No. Faktur | C5: INV-1568 | G5: =IFERROR(MATCH($C$5,Data_Penjualan!$A$2:$A$5998,0),"") -> 5412
A6: Tanggal Faktur | C6: =IFERROR(INDEX(Piutang!$B$2:$B$1751,MATCH($C$5,Piutang!$A$2:$A$1751,0)),"") -> 45987
A7: Customer | C7: =IFERROR(INDEX(Piutang!$D$2:$D$1751,MATCH($C$5,Piutang!$A$2:$A$1751,0)),"") -> BINTANG OLI
A8: Salesman | C8: =IFERROR(INDEX(Piutang!$E$2:$E$1751,MATCH($C$5,Piutang!$A$2:$A$1751,0)),"") -> SALES D
A9: Termin (hari) | C9: =IFERROR(INDEX(Piutang!$G$2:$G$1751,MATCH($C$5,Piutang!$A$2:$A$1751,0)),"") -> 14
A10: Jatuh Tempo | C10: =IFERROR(INDEX(Piutang!$H$2:$H$1751,MATCH($C$5,Piutang!$A$2:$A$1751,0)),"") -> 46001
A12: No | B12: Nama Item | C12: Qty | D12: Unit | E12: Jumlah (Rp)
A13: =IF(B13="","",1) -> 1 | B13: =IFERROR(IF(AND($G$5<>"",INDEX(Data_Penjualan!$A$2:$A$5998,$G$5+0)=$C$5),INDEX(Data_Penjualan!$D$2:$D$5998,$G$5+0),""),"") -> Oli Mesin Mobil Diesel SAE 15W-40 (6x1L) | C13: =IFERROR(IF(AND($G$5<>"",INDEX(Data_Penjualan!$A$2:$A$5998,$G$5+0)=$C$5),INDEX(Data_Penjualan!$E$2:$E$5998,$G$5+0),""),"") -> 7 | D13: =IFERROR(IF(AND($G$5<>"",INDEX(Data_Penjualan!$A$2:$A$5998,$G$5+0)=$C$5),INDEX(Data_Penjualan!$F$2:$F$5998,$G$5+0),""),"") -> DUS | E13: =IFERROR(IF(AND($G$5<>"",INDEX(Data_Penjualan!$A$2:$A$5998,$G$5+0)=$C$5),INDEX(Data_Penjualan!$G$2:$G$5998,$G$5+0),""),"") -> 4268300
A14: =IF(B14="","",2) -> 2 | B14: =IFERROR(IF(AND($G$5<>"",INDEX(Data_Penjualan!$A$2:$A$5998,$G$5+1)=$C$5),INDEX(Data_Penjualan!$D$2:$D$5998,$G$5+1),""),"") -> Oli Hidrolik ISO 68 (1x20L) | C14: =IFERROR(IF(AND($G$5<>"",INDEX(Data_Penjualan!$A$2:$A$5998,$G$5+1)=$C$5),INDEX(Data_Penjualan!$E$2:$E$5998,$G$5+1),""),"") -> 3 | D14: =IFERROR(IF(AND($G$5<>"",INDEX(Data_Penjualan!$A$2:$A$5998,$G$5+1)=$C$5),INDEX(Data_Penjualan!$F$2:$F$5998,$G$5+1),""),"") -> PAIL | E14: =IFERROR(IF(AND($G$5<>"",INDEX(Data_Penjualan!$A$2:$A$5998,$G$5+1)=$C$5),INDEX(Data_Penjualan!$G$2:$G$5998,$G$5+1),""),"") -> 2371100
A15: =IF(B15="","",3) -> 3 | B15: =IFERROR(IF(AND($G$5<>"",INDEX(Data_Penjualan!$A$2:$A$5998,$G$5+2)=$C$5),INDEX(Data_Penjualan!$D$2:$D$5998,$G$5+2),""),"") -> Coolant Radiator Hijau (12x1L) | C15: =IFERROR(IF(AND($G$5<>"",INDEX(Data_Penjualan!$A$2:$A$5998,$G$5+2)=$C$5),INDEX(Data_Penjualan!$E$2:$E$5998,$G$5+2),""),"") -> 4 | D15: =IFERROR(IF(AND($G$5<>"",INDEX(Data_Penjualan!$A$2:$A$5998,$G$5+2)=$C$5),INDEX(Data_Penjualan!$F$2:$F$5998,$G$5+2),""),"") -> DUS | E15: =IFERROR(IF(AND($G$5<>"",INDEX(Data_Penjualan!$A$2:$A$5998,$G$5+2)=$C$5),INDEX(Data_Penjualan!$G$2:$G$5998,$G$5+2),""),"") -> 1761700
A16: =IF(B16="","",4) -> 4 | B16: =IFERROR(IF(AND($G$5<>"",INDEX(Data_Penjualan!$A$2:$A$5998,$G$5+3)=$C$5),INDEX(Data_Penjualan!$D$2:$D$5998,$G$5+3),""),"") -> Oli Mesin Mobil Bensin SAE 10W-40 (6x1L) | C16: =IFERROR(IF(AND($G$5<>"",INDEX(Data_Penjualan!$A$2:$A$5998,$G$5+3)=$C$5),INDEX(Data_Penjualan!$E$2:$E$5998,$G$5+3),""),"") -> 4 | D16: =IFERROR(IF(AND($G$5<>"",INDEX(Data_Penjualan!$A$2:$A$5998,$G$5+3)=$C$5),INDEX(Data_Penjualan!$F$2:$F$5998,$G$5+3),""),"") -> DUS | E16: =IFERROR(IF(AND($G$5<>"",INDEX(Data_Penjualan!$A$2:$A$5998,$G$5+3)=$C$5),INDEX(Data_Penjualan!$G$2:$G$5998,$G$5+3),""),"") -> 2494100
A17: =IF(B17="","",5) -> 5 | B17: =IFERROR(IF(AND($G$5<>"",INDEX(Data_Penjualan!$A$2:$A$5998,$G$5+4)=$C$5),INDEX(Data_Penjualan!$D$2:$D$5998,$G$5+4),""),"") -> Oli Mesin Mobil Bensin SAE 20W-50 (6x1L) | C17: =IFERROR(IF(AND($G$5<>"",INDEX(Data_Penjualan!$A$2:$A$5998,$G$5+4)=$C$5),INDEX(Data_Penjualan!$E$2:$E$5998,$G$5+4),""),"") -> 5 | D17: =IFERROR(IF(AND($G$5<>"",INDEX(Data_Penjualan!$A$2:$A$5998,$G$5+4)=$C$5),INDEX(Data_Penjualan!$F$2:$F$5998,$G$5+4),""),"") -> DUS | E17: =IFERROR(IF(AND($G$5<>"",INDEX(Data_Penjualan!$A$2:$A$5998,$G$5+4)=$C$5),INDEX(Data_Penjualan!$G$2:$G$5998,$G$5+4),""),"") -> 2880000
A18: =IF(B18="","",6) -> 6 | B18: =IFERROR(IF(AND($G$5<>"",INDEX(Data_Penjualan!$A$2:$A$5998,$G$5+5)=$C$5),INDEX(Data_Penjualan!$D$2:$D$5998,$G$5+5),""),"") -> Oli Samping 2T (24x0.8L) | C18: =IFERROR(IF(AND($G$5<>"",INDEX(Data_Penjualan!$A$2:$A$5998,$G$5+5)=$C$5),INDEX(Data_Penjualan!$E$2:$E$5998,$G$5+5),""),"") -> 5 | D18: =IFERROR(IF(AND($G$5<>"",INDEX(Data_Penjualan!$A$2:$A$5998,$G$5+5)=$C$5),INDEX(Data_Penjualan!$F$2:$F$5998,$G$5+5),""),"") -> DUS | E18: =IFERROR(IF(AND($G$5<>"",INDEX(Data_Penjualan!$A$2:$A$5998,$G$5+5)=$C$5),INDEX(Data_Penjualan!$G$2:$G$5998,$G$5+5),""),"") -> 1853500
A19: =IF(B19="","",7) -> 7 | B19: =IFERROR(IF(AND($G$5<>"",INDEX(Data_Penjualan!$A$2:$A$5998,$G$5+6)=$C$5),INDEX(Data_Penjualan!$D$2:$D$5998,$G$5+6),""),"") -> Oli Gear Industri ISO 220 (1x20L) | C19: =IFERROR(IF(AND($G$5<>"",INDEX(Data_Penjualan!$A$2:$A$5998,$G$5+6)=$C$5),INDEX(Data_Penjualan!$E$2:$E$5998,$G$5+6),""),"") -> 6 | D19: =IFERROR(IF(AND($G$5<>"",INDEX(Data_Penjualan!$A$2:$A$5998,$G$5+6)=$C$5),INDEX(Data_Penjualan!$F$2:$F$5998,$G$5+6),""),"") -> PAIL | E19: =IFERROR(IF(AND($G$5<>"",INDEX(Data_Penjualan!$A$2:$A$5998,$G$5+6)=$C$5),INDEX(Data_Penjualan!$G$2:$G$5998,$G$5+6),""),"") -> 5752300
A20: =IF(B20="","",8) | B20: =IFERROR(IF(AND($G$5<>"",INDEX(Data_Penjualan!$A$2:$A$5998,$G$5+7)=$C$5),INDEX(Data_Penjualan!$D$2:$D$5998,$G$5+7),""),"") | C20: =IFERROR(IF(AND($G$5<>"",INDEX(Data_Penjualan!$A$2:$A$5998,$G$5+7)=$C$5),INDEX(Data_Penjualan!$E$2:$E$5998,$G$5+7),""),"") | D20: =IFERROR(IF(AND($G$5<>"",INDEX(Data_Penjualan!$A$2:$A$5998,$G$5+7)=$C$5),INDEX(Data_Penjualan!$F$2:$F$5998,$G$5+7),""),"") | E20: =IFERROR(IF(AND($G$5<>"",INDEX(Data_Penjualan!$A$2:$A$5998,$G$5+7)=$C$5),INDEX(Data_Penjualan!$G$2:$G$5998,$G$5+7),""),"")
A21: =IF(B21="","",9) | B21: =IFERROR(IF(AND($G$5<>"",INDEX(Data_Penjualan!$A$2:$A$5998,$G$5+8)=$C$5),INDEX(Data_Penjualan!$D$2:$D$5998,$G$5+8),""),"") | C21: =IFERROR(IF(AND($G$5<>"",INDEX(Data_Penjualan!$A$2:$A$5998,$G$5+8)=$C$5),INDEX(Data_Penjualan!$E$2:$E$5998,$G$5+8),""),"") | D21: =IFERROR(IF(AND($G$5<>"",INDEX(Data_Penjualan!$A$2:$A$5998,$G$5+8)=$C$5),INDEX(Data_Penjualan!$F$2:$F$5998,$G$5+8),""),"") | E21: =IFERROR(IF(AND($G$5<>"",INDEX(Data_Penjualan!$A$2:$A$5998,$G$5+8)=$C$5),INDEX(Data_Penjualan!$G$2:$G$5998,$G$5+8),""),"")
A22: =IF(B22="","",10) | B22: =IFERROR(IF(AND($G$5<>"",INDEX(Data_Penjualan!$A$2:$A$5998,$G$5+9)=$C$5),INDEX(Data_Penjualan!$D$2:$D$5998,$G$5+9),""),"") | C22: =IFERROR(IF(AND($G$5<>"",INDEX(Data_Penjualan!$A$2:$A$5998,$G$5+9)=$C$5),INDEX(Data_Penjualan!$E$2:$E$5998,$G$5+9),""),"") | D22: =IFERROR(IF(AND($G$5<>"",INDEX(Data_Penjualan!$A$2:$A$5998,$G$5+9)=$C$5),INDEX(Data_Penjualan!$F$2:$F$5998,$G$5+9),""),"") | E22: =IFERROR(IF(AND($G$5<>"",INDEX(Data_Penjualan!$A$2:$A$5998,$G$5+9)=$C$5),INDEX(Data_Penjualan!$G$2:$G$5998,$G$5+9),""),"")
A23: =IF(B23="","",11) | B23: =IFERROR(IF(AND($G$5<>"",INDEX(Data_Penjualan!$A$2:$A$5998,$G$5+10)=$C$5),INDEX(Data_Penjualan!$D$2:$D$5998,$G$5+10),""),"") | C23: =IFERROR(IF(AND($G$5<>"",INDEX(Data_Penjualan!$A$2:$A$5998,$G$5+10)=$C$5),INDEX(Data_Penjualan!$E$2:$E$5998,$G$5+10),""),"") | D23: =IFERROR(IF(AND($G$5<>"",INDEX(Data_Penjualan!$A$2:$A$5998,$G$5+10)=$C$5),INDEX(Data_Penjualan!$F$2:$F$5998,$G$5+10),""),"") | E23: =IFERROR(IF(AND($G$5<>"",INDEX(Data_Penjualan!$A$2:$A$5998,$G$5+10)=$C$5),INDEX(Data_Penjualan!$G$2:$G$5998,$G$5+10),""),"")
A24: =IF(B24="","",12) | B24: =IFERROR(IF(AND($G$5<>"",INDEX(Data_Penjualan!$A$2:$A$5998,$G$5+11)=$C$5),INDEX(Data_Penjualan!$D$2:$D$5998,$G$5+11),""),"") | C24: =IFERROR(IF(AND($G$5<>"",INDEX(Data_Penjualan!$A$2:$A$5998,$G$5+11)=$C$5),INDEX(Data_Penjualan!$E$2:$E$5998,$G$5+11),""),"") | D24: =IFERROR(IF(AND($G$5<>"",INDEX(Data_Penjualan!$A$2:$A$5998,$G$5+11)=$C$5),INDEX(Data_Penjualan!$F$2:$F$5998,$G$5+11),""),"") | E24: =IFERROR(IF(AND($G$5<>"",INDEX(Data_Penjualan!$A$2:$A$5998,$G$5+11)=$C$5),INDEX(Data_Penjualan!$G$2:$G$5998,$G$5+11),""),"")
A25: =IF(B25="","",13) | B25: =IFERROR(IF(AND($G$5<>"",INDEX(Data_Penjualan!$A$2:$A$5998,$G$5+12)=$C$5),INDEX(Data_Penjualan!$D$2:$D$5998,$G$5+12),""),"") | C25: =IFERROR(IF(AND($G$5<>"",INDEX(Data_Penjualan!$A$2:$A$5998,$G$5+12)=$C$5),INDEX(Data_Penjualan!$E$2:$E$5998,$G$5+12),""),"") | D25: =IFERROR(IF(AND($G$5<>"",INDEX(Data_Penjualan!$A$2:$A$5998,$G$5+12)=$C$5),INDEX(Data_Penjualan!$F$2:$F$5998,$G$5+12),""),"") | E25: =IFERROR(IF(AND($G$5<>"",INDEX(Data_Penjualan!$A$2:$A$5998,$G$5+12)=$C$5),INDEX(Data_Penjualan!$G$2:$G$5998,$G$5+12),""),"")
A26: =IF(B26="","",14) | B26: =IFERROR(IF(AND($G$5<>"",INDEX(Data_Penjualan!$A$2:$A$5998,$G$5+13)=$C$5),INDEX(Data_Penjualan!$D$2:$D$5998,$G$5+13),""),"") | C26: =IFERROR(IF(AND($G$5<>"",INDEX(Data_Penjualan!$A$2:$A$5998,$G$5+13)=$C$5),INDEX(Data_Penjualan!$E$2:$E$5998,$G$5+13),""),"") | D26: =IFERROR(IF(AND($G$5<>"",INDEX(Data_Penjualan!$A$2:$A$5998,$G$5+13)=$C$5),INDEX(Data_Penjualan!$F$2:$F$5998,$G$5+13),""),"") | E26: =IFERROR(IF(AND($G$5<>"",INDEX(Data_Penjualan!$A$2:$A$5998,$G$5+13)=$C$5),INDEX(Data_Penjualan!$G$2:$G$5998,$G$5+13),""),"")
A27: =IF(B27="","",15) | B27: =IFERROR(IF(AND($G$5<>"",INDEX(Data_Penjualan!$A$2:$A$5998,$G$5+14)=$C$5),INDEX(Data_Penjualan!$D$2:$D$5998,$G$5+14),""),"") | C27: =IFERROR(IF(AND($G$5<>"",INDEX(Data_Penjualan!$A$2:$A$5998,$G$5+14)=$C$5),INDEX(Data_Penjualan!$E$2:$E$5998,$G$5+14),""),"") | D27: =IFERROR(IF(AND($G$5<>"",INDEX(Data_Penjualan!$A$2:$A$5998,$G$5+14)=$C$5),INDEX(Data_Penjualan!$F$2:$F$5998,$G$5+14),""),"") | E27: =IFERROR(IF(AND($G$5<>"",INDEX(Data_Penjualan!$A$2:$A$5998,$G$5+14)=$C$5),INDEX(Data_Penjualan!$G$2:$G$5998,$G$5+14),""),"")
A28: =IF(B28="","",16) | B28: =IFERROR(IF(AND($G$5<>"",INDEX(Data_Penjualan!$A$2:$A$5998,$G$5+15)=$C$5),INDEX(Data_Penjualan!$D$2:$D$5998,$G$5+15),""),"") | C28: =IFERROR(IF(AND($G$5<>"",INDEX(Data_Penjualan!$A$2:$A$5998,$G$5+15)=$C$5),INDEX(Data_Penjualan!$E$2:$E$5998,$G$5+15),""),"") | D28: =IFERROR(IF(AND($G$5<>"",INDEX(Data_Penjualan!$A$2:$A$5998,$G$5+15)=$C$5),INDEX(Data_Penjualan!$F$2:$F$5998,$G$5+15),""),"") | E28: =IFERROR(IF(AND($G$5<>"",INDEX(Data_Penjualan!$A$2:$A$5998,$G$5+15)=$C$5),INDEX(Data_Penjualan!$G$2:$G$5998,$G$5+15),""),"")
A29: =IF(B29="","",17) | B29: =IFERROR(IF(AND($G$5<>"",INDEX(Data_Penjualan!$A$2:$A$5998,$G$5+16)=$C$5),INDEX(Data_Penjualan!$D$2:$D$5998,$G$5+16),""),"") | C29: =IFERROR(IF(AND($G$5<>"",INDEX(Data_Penjualan!$A$2:$A$5998,$G$5+16)=$C$5),INDEX(Data_Penjualan!$E$2:$E$5998,$G$5+16),""),"") | D29: =IFERROR(IF(AND($G$5<>"",INDEX(Data_Penjualan!$A$2:$A$5998,$G$5+16)=$C$5),INDEX(Data_Penjualan!$F$2:$F$5998,$G$5+16),""),"") | E29: =IFERROR(IF(AND($G$5<>"",INDEX(Data_Penjualan!$A$2:$A$5998,$G$5+16)=$C$5),INDEX(Data_Penjualan!$G$2:$G$5998,$G$5+16),""),"")
A30: =IF(B30="","",18) | B30: =IFERROR(IF(AND($G$5<>"",INDEX(Data_Penjualan!$A$2:$A$5998,$G$5+17)=$C$5),INDEX(Data_Penjualan!$D$2:$D$5998,$G$5+17),""),"") | C30: =IFERROR(IF(AND($G$5<>"",INDEX(Data_Penjualan!$A$2:$A$5998,$G$5+17)=$C$5),INDEX(Data_Penjualan!$E$2:$E$5998,$G$5+17),""),"") | D30: =IFERROR(IF(AND($G$5<>"",INDEX(Data_Penjualan!$A$2:$A$5998,$G$5+17)=$C$5),INDEX(Data_Penjualan!$F$2:$F$5998,$G$5+17),""),"") | E30: =IFERROR(IF(AND($G$5<>"",INDEX(Data_Penjualan!$A$2:$A$5998,$G$5+17)=$C$5),INDEX(Data_Penjualan!$G$2:$G$5998,$G$5+17),""),"")
A31: =IF(B31="","",19) | B31: =IFERROR(IF(AND($G$5<>"",INDEX(Data_Penjualan!$A$2:$A$5998,$G$5+18)=$C$5),INDEX(Data_Penjualan!$D$2:$D$5998,$G$5+18),""),"") | C31: =IFERROR(IF(AND($G$5<>"",INDEX(Data_Penjualan!$A$2:$A$5998,$G$5+18)=$C$5),INDEX(Data_Penjualan!$E$2:$E$5998,$G$5+18),""),"") | D31: =IFERROR(IF(AND($G$5<>"",INDEX(Data_Penjualan!$A$2:$A$5998,$G$5+18)=$C$5),INDEX(Data_Penjualan!$F$2:$F$5998,$G$5+18),""),"") | E31: =IFERROR(IF(AND($G$5<>"",INDEX(Data_Penjualan!$A$2:$A$5998,$G$5+18)=$C$5),INDEX(Data_Penjualan!$G$2:$G$5998,$G$5+18),""),"")
A32: =IF(B32="","",20) | B32: =IFERROR(IF(AND($G$5<>"",INDEX(Data_Penjualan!$A$2:$A$5998,$G$5+19)=$C$5),INDEX(Data_Penjualan!$D$2:$D$5998,$G$5+19),""),"") | C32: =IFERROR(IF(AND($G$5<>"",INDEX(Data_Penjualan!$A$2:$A$5998,$G$5+19)=$C$5),INDEX(Data_Penjualan!$E$2:$E$5998,$G$5+19),""),"") | D32: =IFERROR(IF(AND($G$5<>"",INDEX(Data_Penjualan!$A$2:$A$5998,$G$5+19)=$C$5),INDEX(Data_Penjualan!$F$2:$F$5998,$G$5+19),""),"") | E32: =IFERROR(IF(AND($G$5<>"",INDEX(Data_Penjualan!$A$2:$A$5998,$G$5+19)=$C$5),INDEX(Data_Penjualan!$G$2:$G$5998,$G$5+19),""),"")
D33: Total Faktur | E33: =IFERROR(INDEX(Piutang!$F$2:$F$1751,MATCH($C$5,Piutang!$A$2:$A$1751,0)),0) -> 21381000
D34: Sudah Dibayar | E34: =IFERROR(INDEX(Piutang!$K$2:$K$1751,MATCH($C$5,Piutang!$A$2:$A$1751,0)),0) -> 0
D35: Sisa Tagihan | E35: =E33-E34 -> 21381000
D36: Status | E36: =IFERROR(INDEX(Piutang!$N$2:$N$1751,MATCH($C$5,Piutang!$A$2:$A$1751,0)),"") -> Belum Bayar
A38: =IF(COUNTIF(Data_Penjualan!$A$2:$A$5998,$C$5)>20,"Catatan: faktur memiliki "&COUNTIF(Data_Penjualan!$A$2:$A$5998,$C$5)&" baris item; lembar ini menampilkan 20 baris pertama, total tetap mencakup seluruh item.","")
A40: Diterima oleh, | E40: Hormat kami,
A44: (............................) | E44: (............................)

Sheet Jadwal_Tagih
A1: JADWAL PENAGIHAN HARIAN
A2: Tanggal kerja | B2: =Catatan!B3 -> 46022
A3: Daftar 25 faktur overdue paling mendesak (urut hari terlambat terbesar). Kolom K-L diisi saat di lapangan; hasil resmi dicatat di sheet Log_Penagihan.
A5: No | B5: No. Invoice | C5: Nama Customer | D5: Salesman | E5: Sisa Piutang (Rp) | F5: Jatuh Tempo | G5: Hari Terlambat | H5: Prioritas | I5: Status Tukar Faktur | J5: Catatan Terakhir | K5: Hasil Kunjungan | L5: Tgl Janji Bayar | M5: Baris (helper)
A6: 1 | B6: =IF($M6="","",INDEX(Piutang!$A$2:$A$1751,$M6)) -> INV-0040 | C6: =IF($M6="","",INDEX(Piutang!$D$2:$D$1751,$M6)) -> CAHAYA OLI | D6: =IF($M6="","",INDEX(Piutang!$E$2:$E$1751,$M6)) -> SALES A | E6: =IF($M6="","",INDEX(Piutang!$M$2:$M$1751,$M6)) -> 1948100 | F6: =IF($M6="","",INDEX(Piutang!$H$2:$H$1751,$M6)) -> 45697 | G6: =IF($M6="","",INDEX(Piutang!$O$2:$O$1751,$M6)) -> 325 | H6: =IF($M6="","",INDEX(Piutang!$R$2:$R$1751,$M6)) -> 1-Tinggi | I6: =IF($M6="","",INDEX(Piutang!$J$2:$J$1751,$M6)) -> Sudah ditukar | J6: =IF($M6="","",INDEX(Piutang!$Q$2:$Q$1751,$M6)) -> Sudah dihubungi via WA, janji bayar minggu depan | M6: =IFERROR(MATCH(LARGE(Piutang!$S$2:$S$1751,A6),Piutang!$S$2:$S$1751,0),"") -> 40
A7: 2 | B7: =IF($M7="","",INDEX(Piutang!$A$2:$A$1751,$M7)) -> INV-0113 | C7: =IF($M7="","",INDEX(Piutang!$D$2:$D$1751,$M7)) -> PRIMA TEKNIK | D7: =IF($M7="","",INDEX(Piutang!$E$2:$E$1751,$M7)) -> SALES D | E7: =IF($M7="","",INDEX(Piutang!$M$2:$M$1751,$M7)) -> 5680100 | F7: =IF($M7="","",INDEX(Piutang!$H$2:$H$1751,$M7)) -> 45715 | G7: =IF($M7="","",INDEX(Piutang!$O$2:$O$1751,$M7)) -> 307 | H7: =IF($M7="","",INDEX(Piutang!$R$2:$R$1751,$M7)) -> 1-Tinggi | I7: =IF($M7="","",INDEX(Piutang!$J$2:$J$1751,$M7)) -> Sudah ditukar | J7: =IF($M7="","",INDEX(Piutang!$Q$2:$Q$1751,$M7)) -> Outlet menunda bayar, perlu kunjungan ulang | M7: =IFERROR(MATCH(LARGE(Piutang!$S$2:$S$1751,A7),Piutang!$S$2:$S$1751,0),"") -> 113
A8: 3 | B8: =IF($M8="","",INDEX(Piutang!$A$2:$A$1751,$M8)) -> INV-0219 | C8: =IF($M8="","",INDEX(Piutang!$D$2:$D$1751,$M8)) -> UTAMA MOTOR | D8: =IF($M8="","",INDEX(Piutang!$E$2:$E$1751,$M8)) -> SALES C | E8: =IF($M8="","",INDEX(Piutang!$M$2:$M$1751,$M8)) -> 5052500 | F8: =IF($M8="","",INDEX(Piutang!$H$2:$H$1751,$M8)) -> 45720 | G8: =IF($M8="","",INDEX(Piutang!$O$2:$O$1751,$M8)) -> 302 | H8: =IF($M8="","",INDEX(Piutang!$R$2:$R$1751,$M8)) -> 1-Tinggi | I8: =IF($M8="","",INDEX(Piutang!$J$2:$J$1751,$M8)) -> Sudah ditukar | J8: =IF($M8="","",INDEX(Piutang!$Q$2:$Q$1751,$M8)) -> Sudah dihubungi via WA, janji bayar minggu depan | M8: =IFERROR(MATCH(LARGE(Piutang!$S$2:$S$1751,A8),Piutang!$S$2:$S$1751,0),"") -> 219
A9: 4 | B9: =IF($M9="","",INDEX(Piutang!$A$2:$A$1751,$M9)) -> INV-0161 | C9: =IF($M9="","",INDEX(Piutang!$D$2:$D$1751,$M9)) -> SINAR GARAGE | D9: =IF($M9="","",INDEX(Piutang!$E$2:$E$1751,$M9)) -> SALES A | E9: =IF($M9="","",INDEX(Piutang!$M$2:$M$1751,$M9)) -> 1529700 | F9: =IF($M9="","",INDEX(Piutang!$H$2:$H$1751,$M9)) -> 45723 | G9: =IF($M9="","",INDEX(Piutang!$O$2:$O$1751,$M9)) -> 299 | H9: =IF($M9="","",INDEX(Piutang!$R$2:$R$1751,$M9)) -> 1-Tinggi | I9: =IF($M9="","",INDEX(Piutang!$J$2:$J$1751,$M9)) -> Sudah ditukar | J9: =IF($M9="","",INDEX(Piutang!$Q$2:$Q$1751,$M9)) -> Kunjungan tagih dijadwalkan | M9: =IFERROR(MATCH(LARGE(Piutang!$S$2:$S$1751,A9),Piutang!$S$2:$S$1751,0),"") -> 161
A10: 5 | B10: =IF($M10="","",INDEX(Piutang!$A$2:$A$1751,$M10)) -> INV-0240 | C10: =IF($M10="","",INDEX(Piutang!$D$2:$D$1751,$M10)) -> BERKAH MOBIL MAKMUR | D10: =IF($M10="","",INDEX(Piutang!$E$2:$E$1751,$M10)) -> SALES D | E10: =IF($M10="","",INDEX(Piutang!$M$2:$M$1751,$M10)) -> 16047200 | F10: =IF($M10="","",INDEX(Piutang!$H$2:$H$1751,$M10)) -> 45724 | G10: =IF($M10="","",INDEX(Piutang!$O$2:$O$1751,$M10)) -> 298 | H10: =IF($M10="","",INDEX(Piutang!$R$2:$R$1751,$M10)) -> 1-Tinggi | I10: =IF($M10="","",INDEX(Piutang!$J$2:$J$1751,$M10)) -> Sudah ditukar | J10: =IF($M10="","",INDEX(Piutang!$Q$2:$Q$1751,$M10)) -> Eskalasi ke supervisor | M10: =IFERROR(MATCH(LARGE(Piutang!$S$2:$S$1751,A10),Piutang!$S$2:$S$1751,0),"") -> 240
A11: 6 | B11: =IF($M11="","",INDEX(Piutang!$A$2:$A$1751,$M11)) -> INV-0178 | C11: =IF($M11="","",INDEX(Piutang!$D$2:$D$1751,$M11)) -> MITRA BENGKEL | D11: =IF($M11="","",INDEX(Piutang!$E$2:$E$1751,$M11)) -> SALES A | E11: =IF($M11="","",INDEX(Piutang!$M$2:$M$1751,$M11)) -> 8904800 | F11: =IF($M11="","",INDEX(Piutang!$H$2:$H$1751,$M11)) -> 45725 | G11: =IF($M11="","",INDEX(Piutang!$O$2:$O$1751,$M11)) -> 297 | H11: =IF($M11="","",INDEX(Piutang!$R$2:$R$1751,$M11)) -> 1-Tinggi | I11: =IF($M11="","",INDEX(Piutang!$J$2:$J$1751,$M11)) -> Sudah ditukar | J11: =IF($M11="","",INDEX(Piutang!$Q$2:$Q$1751,$M11)) -> Surat peringatan (SP) 1 dikirim | M11: =IFERROR(MATCH(LARGE(Piutang!$S$2:$S$1751,A11),Piutang!$S$2:$S$1751,0),"") -> 178
A12: 7 | B12: =IF($M12="","",INDEX(Piutang!$A$2:$A$1751,$M12)) -> INV-0109 | C12: =IF($M12="","",INDEX(Piutang!$D$2:$D$1751,$M12)) -> KARYA SPAREPART | D12: =IF($M12="","",INDEX(Piutang!$E$2:$E$1751,$M12)) -> SALES B | E12: =IF($M12="","",INDEX(Piutang!$M$2:$M$1751,$M12)) -> 1732600 | F12: =IF($M12="","",INDEX(Piutang!$H$2:$H$1751,$M12)) -> 45727 | G12: =IF($M12="","",INDEX(Piutang!$O$2:$O$1751,$M12)) -> 295 | H12: =IF($M12="","",INDEX(Piutang!$R$2:$R$1751,$M12)) -> 1-Tinggi | I12: =IF($M12="","",INDEX(Piutang!$J$2:$J$1751,$M12)) -> Sudah ditukar | J12: =IF($M12="","",INDEX(Piutang!$Q$2:$Q$1751,$M12)) -> Janji bayar tanggal 10 Jan 2026 | M12: =IFERROR(MATCH(LARGE(Piutang!$S$2:$S$1751,A12),Piutang!$S$2:$S$1751,0),"") -> 109
A13: 8 | B13: =IF($M13="","",INDEX(Piutang!$A$2:$A$1751,$M13)) -> INV-0261 | C13: =IF($M13="","",INDEX(Piutang!$D$2:$D$1751,$M13)) -> PRIMA MOTOR LANCAR | D13: =IF($M13="","",INDEX(Piutang!$E$2:$E$1751,$M13)) -> SALES B | E13: =IF($M13="","",INDEX(Piutang!$M$2:$M$1751,$M13)) -> 5950800 | F13: =IF($M13="","",INDEX(Piutang!$H$2:$H$1751,$M13)) -> 45729 | G13: =IF($M13="","",INDEX(Piutang!$O$2:$O$1751,$M13)) -> 293 | H13: =IF($M13="","",INDEX(Piutang!$R$2:$R$1751,$M13)) -> 1-Tinggi | I13: =IF($M13="","",INDEX(Piutang!$J$2:$J$1751,$M13)) -> Sudah ditukar | J13: =IF($M13="","",INDEX(Piutang!$Q$2:$Q$1751,$M13)) -> Kunjungan tagih dijadwalkan | M13: =IFERROR(MATCH(LARGE(Piutang!$S$2:$S$1751,A13),Piutang!$S$2:$S$1751,0),"") -> 261
A14: 9 | B14: =IF($M14="","",INDEX(Piutang!$A$2:$A$1751,$M14)) -> INV-0226 | C14: =IF($M14="","",INDEX(Piutang!$D$2:$D$1751,$M14)) -> MITRA GARAGE | D14: =IF($M14="","",INDEX(Piutang!$E$2:$E$1751,$M14)) -> SALES A | E14: =IF($M14="","",INDEX(Piutang!$M$2:$M$1751,$M14)) -> 2209000 | F14: =IF($M14="","",INDEX(Piutang!$H$2:$H$1751,$M14)) -> 45752 | G14: =IF($M14="","",INDEX(Piutang!$O$2:$O$1751,$M14)) -> 270 | H14: =IF($M14="","",INDEX(Piutang!$R$2:$R$1751,$M14)) -> 1-Tinggi | I14: =IF($M14="","",INDEX(Piutang!$J$2:$J$1751,$M14)) -> Sudah ditukar | J14: =IF($M14="","",INDEX(Piutang!$Q$2:$Q$1751,$M14)) -> Kunjungan tagih dijadwalkan | M14: =IFERROR(MATCH(LARGE(Piutang!$S$2:$S$1751,A14),Piutang!$S$2:$S$1751,0),"") -> 226
A15: 10 | B15: =IF($M15="","",INDEX(Piutang!$A$2:$A$1751,$M15)) -> INV-0282 | C15: =IF($M15="","",INDEX(Piutang!$D$2:$D$1751,$M15)) -> HARAPAN MOTOR | D15: =IF($M15="","",INDEX(Piutang!$E$2:$E$1751,$M15)) -> SALES C | E15: =IF($M15="","",INDEX(Piutang!$M$2:$M$1751,$M15)) -> 11783000 | F15: =IF($M15="","",INDEX(Piutang!$H$2:$H$1751,$M15)) -> 45762 | G15: =IF($M15="","",INDEX(Piutang!$O$2:$O$1751,$M15)) -> 260 | H15: =IF($M15="","",INDEX(Piutang!$R$2:$R$1751,$M15)) -> 1-Tinggi | I15: =IF($M15="","",INDEX(Piutang!$J$2:$J$1751,$M15)) -> Sudah ditukar | J15: =IF($M15="","",INDEX(Piutang!$Q$2:$Q$1751,$M15)) -> Kunjungan tagih dijadwalkan | M15: =IFERROR(MATCH(LARGE(Piutang!$S$2:$S$1751,A15),Piutang!$S$2:$S$1751,0),"") -> 282
A16: 11 | B16: =IF($M16="","",INDEX(Piutang!$A$2:$A$1751,$M16)) -> INV-0409 | C16: =IF($M16="","",INDEX(Piutang!$D$2:$D$1751,$M16)) -> GEMILANG TEKNIK | D16: =IF($M16="","",INDEX(Piutang!$E$2:$E$1751,$M16)) -> SALES B | E16: =IF($M16="","",INDEX(Piutang!$M$2:$M$1751,$M16)) -> 7894400 | F16: =IF($M16="","",INDEX(Piutang!$H$2:$H$1751,$M16)) -> 45777 | G16: =IF($M16="","",INDEX(Piutang!$O$2:$O$1751,$M16)) -> 245 | H16: =IF($M16="","",INDEX(Piutang!$R$2:$R$1751,$M16)) -> 1-Tinggi | I16: =IF($M16="","",INDEX(Piutang!$J$2:$J$1751,$M16)) -> Sudah ditukar | J16: =IF($M16="","",INDEX(Piutang!$Q$2:$Q$1751,$M16)) -> Kunjungan tagih dijadwalkan | M16: =IFERROR(MATCH(LARGE(Piutang!$S$2:$S$1751,A16),Piutang!$S$2:$S$1751,0),"") -> 409
A17: 12 | B17: =IF($M17="","",INDEX(Piutang!$A$2:$A$1751,$M17)) -> INV-0438 | C17: =IF($M17="","",INDEX(Piutang!$D$2:$D$1751,$M17)) -> SUMBER TEKNIK SURYA | D17: =IF($M17="","",INDEX(Piutang!$E$2:$E$1751,$M17)) -> SALES D | E17: =IF($M17="","",INDEX(Piutang!$M$2:$M$1751,$M17)) -> 5142900 | F17: =IF($M17="","",INDEX(Piutang!$H$2:$H$1751,$M17)) -> 45784 | G17: =IF($M17="","",INDEX(Piutang!$O$2:$O$1751,$M17)) -> 238 | H17: =IF($M17="","",INDEX(Piutang!$R$2:$R$1751,$M17)) -> 1-Tinggi | I17: =IF($M17="","",INDEX(Piutang!$J$2:$J$1751,$M17)) -> Sudah ditukar | J17: =IF($M17="","",INDEX(Piutang!$Q$2:$Q$1751,$M17)) -> Menunggu pencairan giro | M17: =IFERROR(MATCH(LARGE(Piutang!$S$2:$S$1751,A17),Piutang!$S$2:$S$1751,0),"") -> 438
... A30: 25 | B30: =IF($M30="","",INDEX(Piutang!$A$2:$A$1751,$M30)) -> INV-1176 | C30: =IF($M30="","",INDEX(Piutang!$D$2:$D$1751,$M30)) -> ABADI AUTO SURYA | D30: =IF($M30="","",INDEX(Piutang!$E$2:$E$1751,$M30)) -> SALES D | E30: =IF($M30="","",INDEX(Piutang!$M$2:$M$1751,$M30)) -> 4237200 | F30: =IF($M30="","",INDEX(Piutang!$H$2:$H$1751,$M30)) -> 45922 | G30: =IF($M30="","",INDEX(Piutang!$O$2:$O$1751,$M30)) -> 100 | H30: =IF($M30="","",INDEX(Piutang!$R$2:$R$1751,$M30)) -> 1-Tinggi | I30: =IF($M30="","",INDEX(Piutang!$J$2:$J$1751,$M30)) -> Sudah ditukar | J30: =IF($M30="","",INDEX(Piutang!$Q$2:$Q$1751,$M30)) -> Eskalasi ke supervisor | M30: =IFERROR(MATCH(LARGE(Piutang!$S$2:$S$1751,A30),Piutang!$S$2:$S$1751,0),"") -> 1176
D31: TOTAL | E31: =SUM(E6:E30) -> 142849200

Sheet Tukar_Faktur
A1: TRACKER TUKAR FAKTUR
A2: Faktur yang belum ditukar: | C2: =COUNTIF(Piutang!$J$2:$J$1751,"Belum ditukar") -> 9
A3: Tampil maks. 20 faktur terlama. Isi kolom H (rencana tukar), lalu update Tgl Tukar Faktur di sheet Piutang kalau sudah ditukar.
A5: No | B5: No. Invoice | C5: Nama Customer | D5: Salesman | E5: Tgl Faktur | F5: Nominal (Rp) | G5: Umur Faktur (hari) | H5: Rencana Tukar | I5: Baris (helper)
A6: 1 | B6: =IF($I6="","",INDEX(Piutang!$A$2:$A$1751,$I6)) -> INV-1730 | C6: =IF($I6="","",INDEX(Piutang!$D$2:$D$1751,$I6)) -> BINTANG TEKNIK | D6: =IF($I6="","",INDEX(Piutang!$E$2:$E$1751,$I6)) -> SALES A | E6: =IF($I6="","",INDEX(Piutang!$B$2:$B$1751,$I6)) -> 46020 | F6: =IF($I6="","",INDEX(Piutang!$F$2:$F$1751,$I6)) -> 12035400 | G6: =IF($I6="","",Catatan!$B$3-E6) -> 2 | I6: =IFERROR(SMALL(Piutang!$T$2:$T$1751,A6)-1,"") -> 1730
A7: 2 | B7: =IF($I7="","",INDEX(Piutang!$A$2:$A$1751,$I7)) -> INV-1732 | C7: =IF($I7="","",INDEX(Piutang!$D$2:$D$1751,$I7)) -> UTAMA MOTOR | D7: =IF($I7="","",INDEX(Piutang!$E$2:$E$1751,$I7)) -> SALES C | E7: =IF($I7="","",INDEX(Piutang!$B$2:$B$1751,$I7)) -> 46020 | F7: =IF($I7="","",INDEX(Piutang!$F$2:$F$1751,$I7)) -> 375700 | G7: =IF($I7="","",Catatan!$B$3-E7) -> 2 | I7: =IFERROR(SMALL(Piutang!$T$2:$T$1751,A7)-1,"") -> 1732
A8: 3 | B8: =IF($I8="","",INDEX(Piutang!$A$2:$A$1751,$I8)) -> INV-1733 | C8: =IF($I8="","",INDEX(Piutang!$D$2:$D$1751,$I8)) -> CAHAYA MOTOR | D8: =IF($I8="","",INDEX(Piutang!$E$2:$E$1751,$I8)) -> SALES A | E8: =IF($I8="","",INDEX(Piutang!$B$2:$B$1751,$I8)) -> 46020 | F8: =IF($I8="","",INDEX(Piutang!$F$2:$F$1751,$I8)) -> 5431600 | G8: =IF($I8="","",Catatan!$B$3-E8) -> 2 | I8: =IFERROR(SMALL(Piutang!$T$2:$T$1751,A8)-1,"") -> 1733
A9: 4 | B9: =IF($I9="","",INDEX(Piutang!$A$2:$A$1751,$I9)) -> INV-1736 | C9: =IF($I9="","",INDEX(Piutang!$D$2:$D$1751,$I9)) -> KARYA SPAREPART | D9: =IF($I9="","",INDEX(Piutang!$E$2:$E$1751,$I9)) -> SALES B | E9: =IF($I9="","",INDEX(Piutang!$B$2:$B$1751,$I9)) -> 46020 | F9: =IF($I9="","",INDEX(Piutang!$F$2:$F$1751,$I9)) -> 8626200 | G9: =IF($I9="","",Catatan!$B$3-E9) -> 2 | I9: =IFERROR(SMALL(Piutang!$T$2:$T$1751,A9)-1,"") -> 1736
